Workbook
Name AsOfDate: LEEME!$C$6
Name CostPerHour: LEEME!$C$8
Name HS_ARR: E3_Health_Score!$E$8:$E$145
Name HS_Cat: E3_Health_Score!$T$8:$T$145
Name HS_CSM: E3_Health_Score!$D$8:$D$145
Name HS_Days: E3_Health_Score!$N$8:$N$145
Name HS_ID: E3_Health_Score!$A$8:$A$145
Name HS_Name: E3_Health_Score!$B$8:$B$145
Name HS_Score: E3_Health_Score!$S$8:$S$145
Name HS_Segment: E3_Health_Score!$C$8:$C$145
Name HS_Tickets: E3_Health_Score!$L$8:$L$145
Name LastMonth: LEEME!$C$7

Sheet LEEME
A1: Práctica de Excel · Analyst, Customer Success Operations
A2: Versión: PRÁCTICA (llena las celdas amarillas)
B3: Escenario: eres analista de CS Ops en una empresa SaaS B2B. Liderazgo quiere (1) entender la salud de las cuentas para que los CSMs prioricen, (2) auditar los reportes actuales para decidir qué mantener, consolidar, automatizar o retirar, y (3) tener datos limpios y confiables para QBRs/EBRs, renovaciones y reportes contractuales. Todos los datos son ficticios.
B5: Parámetros (usados en todas las fórmulas)
B6: AsOfDate (fecha de corte) | C6: 46295 | D6: Nombre definido AsOfDate. Se usa en lugar de TODAY() para que los resultados sean reproducibles.
B7: LastMonth (último mes cerrado) | C7: =DATE(YEAR(AsOfDate),MONTH(AsOfDate),1) -> 46266 | D7: Nombre definido LastMonth = primer día del mes de AsOfDate.
B8: CostPerHour (USD) | C8: 35 | D8: Costo por hora de analista; se usa para estimar el costo de mantener un reporte.
B10: Cómo usar este libro
B11: 1. Cada hoja E# es un ejercicio. Lee el objetivo (fila 2), el contexto de negocio (fila 3) y la pista gris debajo de cada encabezado.
B12: 2. Escribe tus fórmulas en las celdas AMARILLAS. Las columnas ✓/✗ se validan solas contra la respuesta correcta (oculta). Copia/arrastra la fórmula de la primera fila hacia abajo.
B13: 3. Si te atoras, abre CS_Ops_Soluciones.xlsx (mismo set de datos) y compara tu fórmula.
B14: 4. Los datos están en las hojas grises como Tablas de Excel (tbl_Accounts, tbl_Usage, etc.). Úsalas con referencias estructuradas: tbl_Accounts[ARR_USD]. Revisa la hoja Diccionario.
B15: 5. Las verificaciones asumen los parámetros y pesos por defecto. Si los cambias para experimentar, algunas ✓ pasarán a ✗ (eso es normal).
B16: 6. Regenera el archivo con otra semilla (python generar_practica_excel.py --semilla 123) para practicar de nuevo con números diferentes.
B17: 7. Excel en español: los nombres de funciones se traducen solos al abrir el archivo y el separador puede ser ';' en vez de ','. Abajo a la derecha tienes la tabla de traducción.
B19: Ejercicios y progreso
B20: Hoja | C20: Habilidad clave | D20: Qué practicas / para qué sirve en el puesto | E20: ✓ | F20: Total | G20: Avance
B21: E1_Lookups | C21: Lookups | D21: VLOOKUP, INDEX/MATCH, XLOOKUP anidado, búsqueda aproximada (tiers), búsqueda inversa (último registro), IFERROR y TRIM. | E21: =COUNTIF('E1_Lookups'!$A$1:$BZ$400,"✓") -> 0 | F21: 120 | G21: =IFERROR(E21/F21,0) -> 0
B22: E2_Agregaciones | C22: SUMIFS/COUNTIFS | D22: Matrices ARR segmento×región, book of business por CSM, tickets por prioridad, NPS. Base de cualquier reporte. | E22: =COUNTIF('E2_Agregaciones'!$A$1:$BZ$400,"✓") -> 0 | F22: 101 | G22: =IFERROR(E22/F22,0) -> 0
B23: E3_Health_Score | C23: Health score | D23: Construir un health score ponderado (adopción, tendencia, soporte, NPS), categorías Green/Yellow/Red y riesgo de renovación. | E23: =COUNTIF('E3_Health_Score'!$A$1:$BZ$400,"✓") -> 0 | F23: 976 | G23: =IFERROR(E23/F23,0) -> 0
B24: E4_Auditoria_Reportes | C24: Auditoría de reportes | D24: Uso real de cada reporte, usuarios únicos, última consulta, costo por vista y recomendación (retirar / consolidar / automatizar / mantener). | E24: =COUNTIF('E4_Auditoria_Reportes'!$A$1:$BZ$400,"✓") -> 0 | F24: 272 | G24: =IFERROR(E24/F24,0) -> 0
B25: E5_Limpieza_Datos | C25: Calidad de datos | D25: Limpiar un export del CRM: espacios, mayúsculas, montos y fechas en texto, duplicados, IDs inexistentes y diferencias vs. el maestro. | E25: =COUNTIF('E5_Limpieza_Datos'!$A$1:$BZ$400,"✓") -> 0 | F25: 587 | G25: =IFERROR(E25/F25,0) -> 0
B26: E6_Pivots | C26: Tablas dinámicas | D26: Construir pivots (agrupación por mes, % del total, campos calculados, slicers) y validar con GETPIVOTDATA. | E26: =COUNTIF('E6_Pivots'!$A$1:$BZ$400,"✓") -> 0 | F26: 119 | G26: =IFERROR(E26/F26,0) -> 0
B27: E7_Dinamicas_365 | C27: Matrices dinámicas | D27: FILTER, UNIQUE, SORT, XLOOKUP de varias columnas, TEXTJOIN, LET, SEQUENCE. | E27: =COUNTIF('E7_Dinamicas_365'!$A$1:$BZ$400,"✓") -> 0 | F27: 4 | G27: =IFERROR(E27/F27,0) -> 0
B28: E8_Tendencias | C28: Tendencias y churn | D28: Uso mensual, MoM %, promedio móvil, churn y GRR, pipeline de renovaciones con ARR en riesgo. | E28: =COUNTIF('E8_Tendencias'!$A$1:$BZ$400,"✓") -> 0 | F28: 124 | G28: =IFERROR(E28/F28,0) -> 0
B29: E9_Dashboard_CSM | C29: Dashboard | D29: Tablero para un CSM con lista desplegable, KPIs, top 5 cuentas en riesgo y gráfica. | E29: =COUNTIF('E9_Dashboard_CSM'!$A$1:$BZ$400,"✓") -> 0 | F29: 11 | G29: =IFERROR(E29/F29,0) -> 0
D30: TOTAL | E30: =SUM(E21:E29) -> 0 | F30: =SUM(F21:F29) -> 0 | G30: =IFERROR(E30/F30,0) -> 0
B32: Extras (sin verificación automática)
B33: E10_PowerQuery | D33: Importar y combinar los CSV con Power Query; refrescar.
B34: Entrevista | D34: Preguntas técnicas y de negocio para practicar en voz alta (en inglés).
B35: Diccionario | D35: Qué contiene cada tabla y columna.
B38: Atajos útiles
B39: Ctrl + T | D39: Convertir rango en Tabla
B40: Alt, N, V | D40: Insertar tabla dinámica
B41: F4 | D41: Fijar referencia ($A$1)
B42: Ctrl + Shift + L | D42: Activar filtros
B43: Ctrl + Flecha | D43: Ir al final de los datos
B44: Ctrl + Shift + Flecha | D44: Seleccionar hasta el final
B45: Alt + = | D45: Autosuma
B46: Ctrl + ` | D46: Mostrar fórmulas
...

Sheet Diccionario
A1: Diccionario de datos
A2: Antes de analizar, entiende la granularidad de cada tabla (¿una fila = qué?) y cuáles son las llaves para relacionarlas.
A5: Tabla | B5: Hoja | C5: Columna | D5: Descripción | E5: Filas
A6: tbl_Accounts | B6: Accounts | D6: Maestro de cuentas (1 fila por cliente) | E6: 150
C7: AccountID | D7: ID único de la cuenta (llave primaria)
C8: AccountName | D8: Nombre del cliente
C9: Segment | D9: Enterprise / Mid-Market / SMB
C10: Region | D10: Región comercial
C11: Industry | D11: Industria
C12: Product | D12: Producto principal contratado
C13: CSM_ID | D13: CSM asignado (llave hacia tbl_CSMs)
C14: ARR_USD | D14: Ingreso recurrente anual
C15: LicensedSeats | D15: Licencias contratadas
C16: ContractStart | D16: Inicio de contrato
C17: RenewalDate | D17: Próxima renovación (o fecha de churn si Status = Churned)
C18: Status | D18: Active / Churned
... C20: ContractualReporting | D20: Si el contrato obliga a enviar reportes de uso (Monthly/Quarterly/None)
A21: tbl_CSMs | B21: CSMs | D21: Customer Success Managers | E21: 8
C22: CSM_ID | D22: ID del CSM
C23: CSM_Name | D23: Nombre
C24: Email | D24: Correo
C25: Team | D25: Segmento que atiende
C26: Manager | D26: Líder
A27: tbl_Usage | B27: Usage_Monthly | D27: Uso del producto por cuenta y mes (12 meses) | E27: 1748
C28: AccountID | D28: Cuenta
C29: Month | D29: Primer día del mes
C30: ActiveUsers | D30: Usuarios activos en el mes
C31: Logins | D31: Inicios de sesión
C32: ReportsRun | D32: Reportes ejecutados dentro del producto
C33: FeaturesAdopted | D33: Funcionalidades clave usadas (1-10)
C34: AvgSessionMin | D34: Duración media de sesión
A35: tbl_Tickets | B35: Support_Tickets | D35: Tickets de soporte (último año) | E35: 774
C36: TicketID | D36: ID
C37: AccountID | D37: Cuenta
C38: OpenedDate | D38: Apertura
C39: ClosedDate | D39: Cierre (vacío = abierto)
C40: Priority | D40: P1 (crítico) a P4
C41: Category | D41: Tipo
C42: CSAT | D42: Satisfacción 1-5 (vacío = sin respuesta)
A43: tbl_NPS | B43: NPS | D43: Respuestas de encuesta NPS (algunas > 12 meses) | E43: 178
...

Sheet E1_Lookups
A1: E1 · Lookups: traer datos de otras tablas
A2: Objetivo: un CSM te manda una lista de IDs (copiada de un correo, con espacios y minúsculas) y necesita nombre, segmento, CSM, ARR, tier, uso del último mes y días para la renovación. Practica las 3 familias de búsqueda y cuándo usar cada una.
A3: Contexto: es el trabajo diario de CS Ops — enriquecer listas con datos del CRM. XLOOKUP es el estándar hoy, pero en entrevistas y archivos heredados verás VLOOKUP e INDEX/MATCH.
A5: AccountID (lista del CSM) | B5: AccountName | C5: Segment | D5: CSM_Name | E5: ARR_USD | F5: Tier (aprox.) | G5: Tier (XLOOKUP) | H5: ActiveUsers último registro | I5: Días a renovación | K5: ✓B | L5: ✓C | M5: ✓D | N5: ✓E | O5: ✓F | P5: ✓G | Q5: ✓H | R5: ✓I | T5: Min ARR | U5: Tier
A6: Dato dado (ojo: espacios y minúsculas) | B6: VLOOKUP(TRIM(A7), tbl_Accounts, 2, FALSE) + IFERROR → "No encontrado" | C6: INDEX(tbl_Accounts[Segment], MATCH(TRIM(A7), tbl_Accounts[AccountID], 0)) + IFERROR → "No encontrado" | D6: XLOOKUP anidado: primero el CSM_ID en tbl_Accounts y luego el nombre en tbl_CSMs. IFERROR → "No encontrado" | E6: XLOOKUP con if_not_found = 0 | F6: Si ARR=0 → ""; si no VLOOKUP(E7, $T$7:$U$10, 2, TRUE) (búsqueda aproximada) | G6: Igual pero con XLOOKUP(E7, $T$7:$T$10, $U$7:$U$10, , -1) | H6: XLOOKUP con search_mode -1 (de abajo hacia arriba) en tbl_Usage → último mes con datos. if_not_found → "No encontrado" | I6: IFERROR(XLOOKUP(...RenewalDate) - AsOfDate, "") | T6: Tabla de tiers: ordenada ascendente (requisito de la búsqueda aproximada)
A7: ACC-0010 | K7: =IF(ISBLANK(B7),"",IF(IFERROR(EXACT(B7,'_key'!$A$1),FALSE),"✓","✗")) -> 0 | L7: =IF(ISBLANK(C7),"",IF(IFERROR(EXACT(C7,'_key'!$A$2),FALSE),"✓","✗")) -> 0 | M7: =IF(ISBLANK(D7),"",IF(IFERROR(EXACT(D7,'_key'!$A$3),FALSE),"✓","✗")) -> 0 | N7: =IF(ISBLANK(E7),"",IF(IFERROR(ABS(E7-'_key'!$A$4)<=0.005,FALSE),"✓","✗")) -> 0 | O7: =IF(ISBLANK(F7),"",IF(IFERROR(EXACT(F7,'_key'!$A$5),FALSE),"✓","✗")) -> 0 | P7: =IF(ISBLANK(G7),"",IF(IFERROR(EXACT(G7,'_key'!$A$6),FALSE),"✓","✗")) -> 0 | Q7: =IF(ISBLANK(H7),"",IF(IFERROR(ABS(H7-'_key'!$A$7)<=0.005,FALSE),"✓","✗")) -> 0 | R7: =IF(ISBLANK(I7),"",IF(IFERROR(ABS(I7-'_key'!$A$8)<=0.005,FALSE),"✓","✗")) -> 0 | T7: 0 | U7: Bronze
A8: ACC-0074 | K8: =IF(ISBLANK(B8),"",IF(IFERROR(EXACT(B8,'_key'!$A$9),FALSE),"✓","✗")) -> 0 | L8: =IF(ISBLANK(C8),"",IF(IFERROR(EXACT(C8,'_key'!$A$10),FALSE),"✓","✗")) -> 0 | M8: =IF(ISBLANK(D8),"",IF(IFERROR(EXACT(D8,'_key'!$A$11),FALSE),"✓","✗")) -> 0 | N8: =IF(ISBLANK(E8),"",IF(IFERROR(ABS(E8-'_key'!$A$12)<=0.005,FALSE),"✓","✗")) -> 0 | O8: =IF(ISBLANK(F8),"",IF(IFERROR(EXACT(F8,'_key'!$A$13),FALSE),"✓","✗")) -> 0 | P8: =IF(ISBLANK(G8),"",IF(IFERROR(EXACT(G8,'_key'!$A$14),FALSE),"✓","✗")) -> 0 | Q8: =IF(ISBLANK(H8),"",IF(IFERROR(ABS(H8-'_key'!$A$15)<=0.005,FALSE),"✓","✗")) -> 0 | R8: =IF(ISBLANK(I8),"",IF(IFERROR(ABS(I8-'_key'!$A$16)<=0.005,FALSE),"✓","✗")) -> 0 | T8: 25000 | U8: Silver
A9: ACC-0037 | K9: =IF(ISBLANK(B9),"",IF(IFERROR(EXACT(B9,'_key'!$A$17),FALSE),"✓","✗")) -> 0 | L9: =IF(ISBLANK(C9),"",IF(IFERROR(EXACT(C9,'_key'!$A$18),FALSE),"✓","✗")) -> 0 | M9: =IF(ISBLANK(D9),"",IF(IFERROR(EXACT(D9,'_key'!$A$19),FALSE),"✓","✗")) -> 0 | N9: =IF(ISBLANK(E9),"",IF(IFERROR(ABS(E9-'_key'!$A$20)<=0.005,FALSE),"✓","✗")) -> 0 | O9: =IF(ISBLANK(F9),"",IF(IFERROR(EXACT(F9,'_key'!$A$21),FALSE),"✓","✗")) -> 0 | P9: =IF(ISBLANK(G9),"",IF(IFERROR(EXACT(G9,'_key'!$A$22),FALSE),"✓","✗")) -> 0 | Q9: =IF(ISBLANK(H9),"",IF(IFERROR(ABS(H9-'_key'!$A$23)<=0.005,FALSE),"✓","✗")) -> 0 | R9: =IF(ISBLANK(I9),"",IF(IFERROR(ABS(I9-'_key'!$A$24)<=0.005,FALSE),"✓","✗")) -> 0 | T9: 100000 | U9: Gold
A10: acc-0096 | K10: =IF(ISBLANK(B10),"",IF(IFERROR(EXACT(B10,'_key'!$A$25),FALSE),"✓","✗")) -> 0 | L10: =IF(ISBLANK(C10),"",IF(IFERROR(EXACT(C10,'_key'!$A$26),FALSE),"✓","✗")) -> 0 | M10: =IF(ISBLANK(D10),"",IF(IFERROR(EXACT(D10,'_key'!$A$27),FALSE),"✓","✗")) -> 0 | N10: =IF(ISBLANK(E10),"",IF(IFERROR(ABS(E10-'_key'!$A$28)<=0.005,FALSE),"✓","✗")) -> 0 | O10: =IF(ISBLANK(F10),"",IF(IFERROR(EXACT(F10,'_key'!$A$29),FALSE),"✓","✗")) -> 0 | P10: =IF(ISBLANK(G10),"",IF(IFERROR(EXACT(G10,'_key'!$A$30),FALSE),"✓","✗")) -> 0 | Q10: =IF(ISBLANK(H10),"",IF(IFERROR(ABS(H10-'_key'!$A$31)<=0.005,FALSE),"✓","✗")) -> 0 | R10: =IF(ISBLANK(I10),"",IF(IFERROR(ABS(I10-'_key'!$A$32)<=0.005,FALSE),"✓","✗")) -> 0 | T10: 250000 | U10: Platinum
A11: ACC-0119 | K11: =IF(ISBLANK(B11),"",IF(IFERROR(EXACT(B11,'_key'!$A$33),FALSE),"✓","✗")) -> 0 | L11: =IF(ISBLANK(C11),"",IF(IFERROR(EXACT(C11,'_key'!$A$34),FALSE),"✓","✗")) -> 0 | M11: =IF(ISBLANK(D11),"",IF(IFERROR(EXACT(D11,'_key'!$A$35),FALSE),"✓","✗")) -> 0 | N11: =IF(ISBLANK(E11),"",IF(IFERROR(ABS(E11-'_key'!$A$36)<=0.005,FALSE),"✓","✗")) -> 0 | O11: =IF(ISBLANK(F11),"",IF(IFERROR(EXACT(F11,'_key'!$A$37),FALSE),"✓","✗")) -> 0 | P11: =IF(ISBLANK(G11),"",IF(IFERROR(EXACT(G11,'_key'!$A$38),FALSE),"✓","✗")) -> 0 | Q11: =IF(ISBLANK(H11),"",IF(IFERROR(ABS(H11-'_key'!$A$39)<=0.005,FALSE),"✓","✗")) -> 0 | R11: =IF(ISBLANK(I11),"",IF(IFERROR(ABS(I11-'_key'!$A$40)<=0.005,FALSE),"✓","✗")) -> 0
A12: ACC-0095 | K12: =IF(ISBLANK(B12),"",IF(IFERROR(EXACT(B12,'_key'!$A$41),FALSE),"✓","✗")) -> 0 | L12: =IF(ISBLANK(C12),"",IF(IFERROR(EXACT(C12,'_key'!$A$42),FALSE),"✓","✗")) -> 0 | M12: =IF(ISBLANK(D12),"",IF(IFERROR(EXACT(D12,'_key'!$A$43),FALSE),"✓","✗")) -> 0 | N12: =IF(ISBLANK(E12),"",IF(IFERROR(ABS(E12-'_key'!$A$44)<=0.005,FALSE),"✓","✗")) -> 0 | O12: =IF(ISBLANK(F12),"",IF(IFERROR(EXACT(F12,'_key'!$A$45),FALSE),"✓","✗")) -> 0 | P12: =IF(ISBLANK(G12),"",IF(IFERROR(EXACT(G12,'_key'!$A$46),FALSE),"✓","✗")) -> 0 | Q12: =IF(ISBLANK(H12),"",IF(IFERROR(ABS(H12-'_key'!$A$47)<=0.005,FALSE),"✓","✗")) -> 0 | R12: =IF(ISBLANK(I12),"",IF(IFERROR(ABS(I12-'_key'!$A$48)<=0.005,FALSE),"✓","✗")) -> 0
A13: ACC-0025 | K13: =IF(ISBLANK(B13),"",IF(IFERROR(EXACT(B13,'_key'!$A$49),FALSE),"✓","✗")) -> 0 | L13: =IF(ISBLANK(C13),"",IF(IFERROR(EXACT(C13,'_key'!$A$50),FALSE),"✓","✗")) -> 0 | M13: =IF(ISBLANK(D13),"",IF(IFERROR(EXACT(D13,'_key'!$A$51),FALSE),"✓","✗")) -> 0 | N13: =IF(ISBLANK(E13),"",IF(IFERROR(ABS(E13-'_key'!$A$52)<=0.005,FALSE),"✓","✗")) -> 0 | O13: =IF(ISBLANK(F13),"",IF(IFERROR(EXACT(F13,'_key'!$A$53),FALSE),"✓","✗")) -> 0 | P13: =IF(ISBLANK(G13),"",IF(IFERROR(EXACT(G13,'_key'!$A$54),FALSE),"✓","✗")) -> 0 | Q13: =IF(ISBLANK(H13),"",IF(IFERROR(ABS(H13-'_key'!$A$55)<=0.005,FALSE),"✓","✗")) -> 0 | R13: =IF(ISBLANK(I13),"",IF(IFERROR(ABS(I13-'_key'!$A$56)<=0.005,FALSE),"✓","✗")) -> 0
A14: ACC-9999 | K14: =IF(ISBLANK(B14),"",IF(IFERROR(EXACT(B14,'_key'!$A$57),FALSE),"✓","✗")) -> 0 | L14: =IF(ISBLANK(C14),"",IF(IFERROR(EXACT(C14,'_key'!$A$58),FALSE),"✓","✗")) -> 0 | M14: =IF(ISBLANK(D14),"",IF(IFERROR(EXACT(D14,'_key'!$A$59),FALSE),"✓","✗")) -> 0 | N14: =IF(ISBLANK(E14),"",IF(IFERROR(ABS(E14-'_key'!$A$60)<=0.005,FALSE),"✓","✗")) -> 0 | O14: =IF(ISBLANK(F14),"",IF(IFERROR(EXACT(F14,'_key'!$A$61),FALSE),"✓","✗")) -> 0 | P14: =IF(ISBLANK(G14),"",IF(IFERROR(EXACT(G14,'_key'!$A$62),FALSE),"✓","✗")) -> 0 | Q14: =IF(ISBLANK(H14),"",IF(IFERROR(EXACT(H14,'_key'!$A$63),FALSE),"✓","✗")) -> 0 | R14: =IF(ISBLANK(I14),"",IF(IFERROR(EXACT(I14,'_key'!$A$64),FALSE),"✓","✗")) -> 0
A15: ACC-0117 | K15: =IF(ISBLANK(B15),"",IF(IFERROR(EXACT(B15,'_key'!$A$65),FALSE),"✓","✗")) -> 0 | L15: =IF(ISBLANK(C15),"",IF(IFERROR(EXACT(C15,'_key'!$A$66),FALSE),"✓","✗")) -> 0 | M15: =IF(ISBLANK(D15),"",IF(IFERROR(EXACT(D15,'_key'!$A$67),FALSE),"✓","✗")) -> 0 | N15: =IF(ISBLANK(E15),"",IF(IFERROR(ABS(E15-'_key'!$A$68)<=0.005,FALSE),"✓","✗")) -> 0 | O15: =IF(ISBLANK(F15),"",IF(IFERROR(EXACT(F15,'_key'!$A$69),FALSE),"✓","✗")) -> 0 | P15: =IF(ISBLANK(G15),"",IF(IFERROR(EXACT(G15,'_key'!$A$70),FALSE),"✓","✗")) -> 0 | Q15: =IF(ISBLANK(H15),"",IF(IFERROR(ABS(H15-'_key'!$A$71)<=0.005,FALSE),"✓","✗")) -> 0 | R15: =IF(ISBLANK(I15),"",IF(IFERROR(ABS(I15-'_key'!$A$72)<=0.005,FALSE),"✓","✗")) -> 0
A16: ACC-0128 | K16: =IF(ISBLANK(B16),"",IF(IFERROR(EXACT(B16,'_key'!$A$73),FALSE),"✓","✗")) -> 0 | L16: =IF(ISBLANK(C16),"",IF(IFERROR(EXACT(C16,'_key'!$A$74),FALSE),"✓","✗")) -> 0 | M16: =IF(ISBLANK(D16),"",IF(IFERROR(EXACT(D16,'_key'!$A$75),FALSE),"✓","✗")) -> 0 | N16: =IF(ISBLANK(E16),"",IF(IFERROR(ABS(E16-'_key'!$A$76)<=0.005,FALSE),"✓","✗")) -> 0 | O16: =IF(ISBLANK(F16),"",IF(IFERROR(EXACT(F16,'_key'!$A$77),FALSE),"✓","✗")) -> 0 | P16: =IF(ISBLANK(G16),"",IF(IFERROR(EXACT(G16,'_key'!$A$78),FALSE),"✓","✗")) -> 0 | Q16: =IF(ISBLANK(H16),"",IF(IFERROR(ABS(H16-'_key'!$A$79)<=0.005,FALSE),"✓","✗")) -> 0 | R16: =IF(ISBLANK(I16),"",IF(IFERROR(ABS(I16-'_key'!$A$80)<=0.005,FALSE),"✓","✗")) -> 0
A17: ACC-0005 | K17: =IF(ISBLANK(B17),"",IF(IFERROR(EXACT(B17,'_key'!$A$81),FALSE),"✓","✗")) -> 0 | L17: =IF(ISBLANK(C17),"",IF(IFERROR(EXACT(C17,'_key'!$A$82),FALSE),"✓","✗")) -> 0 | M17: =IF(ISBLANK(D17),"",IF(IFERROR(EXACT(D17,'_key'!$A$83),FALSE),"✓","✗")) -> 0 | N17: =IF(ISBLANK(E17),"",IF(IFERROR(ABS(E17-'_key'!$A$84)<=0.005,FALSE),"✓","✗")) -> 0 | O17: =IF(ISBLANK(F17),"",IF(IFERROR(EXACT(F17,'_key'!$A$85),FALSE),"✓","✗")) -> 0 | P17: =IF(ISBLANK(G17),"",IF(IFERROR(EXACT(G17,'_key'!$A$86),FALSE),"✓","✗")) -> 0 | Q17: =IF(ISBLANK(H17),"",IF(IFERROR(ABS(H17-'_key'!$A$87)<=0.005,FALSE),"✓","✗")) -> 0 | R17: =IF(ISBLANK(I17),"",IF(IFERROR(ABS(I17-'_key'!$A$88)<=0.005,FALSE),"✓","✗")) -> 0
A18: ACC-0141 | K18: =IF(ISBLANK(B18),"",IF(IFERROR(EXACT(B18,'_key'!$A$89),FALSE),"✓","✗")) -> 0 | L18: =IF(ISBLANK(C18),"",IF(IFERROR(EXACT(C18,'_key'!$A$90),FALSE),"✓","✗")) -> 0 | M18: =IF(ISBLANK(D18),"",IF(IFERROR(EXACT(D18,'_key'!$A$91),FALSE),"✓","✗")) -> 0 | N18: =IF(ISBLANK(E18),"",IF(IFERROR(ABS(E18-'_key'!$A$92)<=0.005,FALSE),"✓","✗")) -> 0 | O18: =IF(ISBLANK(F18),"",IF(IFERROR(EXACT(F18,'_key'!$A$93),FALSE),"✓","✗")) -> 0 | P18: =IF(ISBLANK(G18),"",IF(IFERROR(EXACT(G18,'_key'!$A$94),FALSE),"✓","✗")) -> 0 | Q18: =IF(ISBLANK(H18),"",IF(IFERROR(ABS(H18-'_key'!$A$95)<=0.005,FALSE),"✓","✗")) -> 0 | R18: =IF(ISBLANK(I18),"",IF(IFERROR(ABS(I18-'_key'!$A$96)<=0.005,FALSE),"✓","✗")) -> 0
A19: ACC-0132 | K19: =IF(ISBLANK(B19),"",IF(IFERROR(EXACT(B19,'_key'!$A$97),FALSE),"✓","✗")) -> 0 | L19: =IF(ISBLANK(C19),"",IF(IFERROR(EXACT(C19,'_key'!$A$98),FALSE),"✓","✗")) -> 0 | M19: =IF(ISBLANK(D19),"",IF(IFERROR(EXACT(D19,'_key'!$A$99),FALSE),"✓","✗")) -> 0 | N19: =IF(ISBLANK(E19),"",IF(IFERROR(ABS(E19-'_key'!$A$100)<=0.005,FALSE),"✓","✗")) -> 0 | O19: =IF(ISBLANK(F19),"",IF(IFERROR(EXACT(F19,'_key'!$A$101),FALSE),"✓","✗")) -> 0 | P19: =IF(ISBLANK(G19),"",IF(IFERROR(EXACT(G19,'_key'!$A$102),FALSE),"✓","✗")) -> 0 | Q19: =IF(ISBLANK(H19),"",IF(IFERROR(ABS(H19-'_key'!$A$103)<=0.005,FALSE),"✓","✗")) -> 0 | R19: =IF(ISBLANK(I19),"",IF(IFERROR(ABS(I19-'_key'!$A$104)<=0.005,FALSE),"✓","✗")) -> 0
A20: ACC-0111 | K20: =IF(ISBLANK(B20),"",IF(IFERROR(EXACT(B20,'_key'!$A$105),FALSE),"✓","✗")) -> 0 | L20: =IF(ISBLANK(C20),"",IF(IFERROR(EXACT(C20,'_key'!$A$106),FALSE),"✓","✗")) -> 0 | M20: =IF(ISBLANK(D20),"",IF(IFERROR(EXACT(D20,'_key'!$A$107),FALSE),"✓","✗")) -> 0 | N20: =IF(ISBLANK(E20),"",IF(IFERROR(ABS(E20-'_key'!$A$108)<=0.005,FALSE),"✓","✗")) -> 0 | O20: =IF(ISBLANK(F20),"",IF(IFERROR(EXACT(F20,'_key'!$A$109),FALSE),"✓","✗")) -> 0 | P20: =IF(ISBLANK(G20),"",IF(IFERROR(EXACT(G20,'_key'!$A$110),FALSE),"✓","✗")) -> 0 | Q20: =IF(ISBLANK(H20),"",IF(IFERROR(ABS(H20-'_key'!$A$111)<=0.005,FALSE),"✓","✗")) -> 0 | R20: =IF(ISBLANK(I20),"",IF(IFERROR(ABS(I20-'_key'!$A$112)<=0.005,FALSE),"✓","✗")) -> 0
A21: ACC-0148 | K21: =IF(ISBLANK(B21),"",IF(IFERROR(EXACT(B21,'_key'!$A$113),FALSE),"✓","✗")) -> 0 | L21: =IF(ISBLANK(C21),"",IF(IFERROR(EXACT(C21,'_key'!$A$114),FALSE),"✓","✗")) -> 0 | M21: =IF(ISBLANK(D21),"",IF(IFERROR(EXACT(D21,'_key'!$A$115),FALSE),"✓","✗")) -> 0 | N21: =IF(ISBLANK(E21),"",IF(IFERROR(ABS(E21-'_key'!$A$116)<=0.005,FALSE),"✓","✗")) -> 0 | O21: =IF(ISBLANK(F21),"",IF(IFERROR(EXACT(F21,'_key'!$A$117),FALSE),"✓","✗")) -> 0 | P21: =IF(ISBLANK(G21),"",IF(IFERROR(EXACT(G21,'_key'!$A$118),FALSE),"✓","✗")) -> 0 | Q21: =IF(ISBLANK(H21),"",IF(IFERROR(ABS(H21-'_key'!$A$119)<=0.005,FALSE),"✓","✗")) -> 0 | R21: =IF(ISBLANK(I21),"",IF(IFERROR(ABS(I21-'_key'!$A$120)<=0.005,FALSE),"✓","✗")) -> 0
A23: Para pensar (entrevista): ¿por qué VLOOKUP se rompe si alguien inserta una columna en tbl_Accounts? ¿Qué ventajas tiene XLOOKUP (búsqueda a la izquierda, if_not_found, búsqueda inversa, coincidencia aproximada sin ordenar)? ¿Qué pasa con el ID que tiene espacios si no usas TRIM?

Sheet E2_Agregaciones
A1: E2 · Agregaciones condicionales (SUMIFS, COUNTIFS, AVERAGEIFS, MAXIFS, SUMPRODUCT)
A2: Objetivo: responder con fórmulas las preguntas típicas de liderazgo: ¿cuánto ARR activo tenemos por segmento y región? ¿cómo está el book of business de cada CSM? ¿cómo va el backlog de soporte? ¿cuál es nuestro NPS?
A3: Tip: estas mismas preguntas se pueden contestar con una tabla dinámica (E6). Saber hacerlas con fórmulas te permite construir reportes que se actualizan solos y validar los pivots.
A4: 1) ARR activo por Segmento × Región
A5: Segment \ Region | B5: North America | C5: LATAM | D5: EMEA | E5: APAC | F5: Total | J5: Chk | K5: Chk | L5: Chk | M5: Chk | N5: Chk
B6: SUMIFS(tbl_Accounts[ARR_USD], ...[Segment], $A7, ...[Region], B$5, ...[Status], "Active") | C6: Fija fila/columna con $ para arrastrar | F6: SUM de la fila
A7: Enterprise | J7: =IF(ISBLANK(B7),"",IF(IFERROR(ABS(B7-'_key'!$A$121)<=0.005,FALSE),"✓","✗")) -> 0 | K7: =IF(ISBLANK(C7),"",IF(IFERROR(ABS(C7-'_key'!$A$122)<=0.005,FALSE),"✓","✗")) -> 0 | L7: =IF(ISBLANK(D7),"",IF(IFERROR(ABS(D7-'_key'!$A$123)<=0.005,FALSE),"✓","✗")) -> 0 | M7: =IF(ISBLANK(E7),"",IF(IFERROR(ABS(E7-'_key'!$A$124)<=0.005,FALSE),"✓","✗")) -> 0 | N7: =IF(ISBLANK(F7),"",IF(IFERROR(ABS(F7-'_key'!$A$125)<=0.005,FALSE),"✓","✗")) -> 0
A8: Mid-Market | J8: =IF(ISBLANK(B8),"",IF(IFERROR(ABS(B8-'_key'!$A$126)<=0.005,FALSE),"✓","✗")) -> 0 | K8: =IF(ISBLANK(C8),"",IF(IFERROR(ABS(C8-'_key'!$A$127)<=0.005,FALSE),"✓","✗")) -> 0 | L8: =IF(ISBLANK(D8),"",IF(IFERROR(ABS(D8-'_key'!$A$128)<=0.005,FALSE),"✓","✗")) -> 0 | M8: =IF(ISBLANK(E8),"",IF(IFERROR(ABS(E8-'_key'!$A$129)<=0.005,FALSE),"✓","✗")) -> 0 | N8: =IF(ISBLANK(F8),"",IF(IFERROR(ABS(F8-'_key'!$A$130)<=0.005,FALSE),"✓","✗")) -> 0
A9: SMB | J9: =IF(ISBLANK(B9),"",IF(IFERROR(ABS(B9-'_key'!$A$131)<=0.005,FALSE),"✓","✗")) -> 0 | K9: =IF(ISBLANK(C9),"",IF(IFERROR(ABS(C9-'_key'!$A$132)<=0.005,FALSE),"✓","✗")) -> 0 | L9: =IF(ISBLANK(D9),"",IF(IFERROR(ABS(D9-'_key'!$A$133)<=0.005,FALSE),"✓","✗")) -> 0 | M9: =IF(ISBLANK(E9),"",IF(IFERROR(ABS(E9-'_key'!$A$134)<=0.005,FALSE),"✓","✗")) -> 0 | N9: =IF(ISBLANK(F9),"",IF(IFERROR(ABS(F9-'_key'!$A$135)<=0.005,FALSE),"✓","✗")) -> 0
A10: Total | J10: =IF(ISBLANK(B10),"",IF(IFERROR(ABS(B10-'_key'!$A$136)<=0.005,FALSE),"✓","✗")) -> 0 | K10: =IF(ISBLANK(C10),"",IF(IFERROR(ABS(C10-'_key'!$A$137)<=0.005,FALSE),"✓","✗")) -> 0 | L10: =IF(ISBLANK(D10),"",IF(IFERROR(ABS(D10-'_key'!$A$138)<=0.005,FALSE),"✓","✗")) -> 0 | M10: =IF(ISBLANK(E10),"",IF(IFERROR(ABS(E10-'_key'!$A$139)<=0.005,FALSE),"✓","✗")) -> 0 | N10: =IF(ISBLANK(F10),"",IF(IFERROR(ABS(F10-'_key'!$A$140)<=0.005,FALSE),"✓","✗")) -> 0
A13: 2) Book of business por CSM (solo cuentas activas)
A14: CSM_ID | B14: CSM_Name | C14: # Cuentas | D14: ARR | E14: ARR promedio | F14: Cuenta más grande (ARR) | G14: Próxima renovación | H14: % del ARR total | J14: ✓B | K14: ✓C | L14: ✓D | M14: ✓E | N14: ✓F | O14: ✓G | P14: ✓H
A15: Dado | B15: XLOOKUP en tbl_CSMs | C15: COUNTIFS con 2 criterios | D15: SUMIFS | E15: AVERAGEIFS (IFERROR → 0) | F15: MAXIFS | G15: MINIFS sobre RenewalDate | H15: D / SUM($D$...)
A16: CSM-01 | J16: =IF(ISBLANK(B16),"",IF(IFERROR(EXACT(B16,'_key'!$A$141),FALSE),"✓","✗")) -> 0 | K16: =IF(ISBLANK(C16),"",IF(IFERROR(ABS(C16-'_key'!$A$142)<=0.005,FALSE),"✓","✗")) -> 0 | L16: =IF(ISBLANK(D16),"",IF(IFERROR(ABS(D16-'_key'!$A$143)<=0.005,FALSE),"✓","✗")) -> 0 | M16: =IF(ISBLANK(E16),"",IF(IFERROR(ABS(E16-'_key'!$A$144)<=0.005,FALSE),"✓","✗")) -> 0 | N16: =IF(ISBLANK(F16),"",IF(IFERROR(ABS(F16-'_key'!$A$145)<=0.005,FALSE),"✓","✗")) -> 0 | O16: =IF(ISBLANK(G16),"",IF(IFERROR(ABS(G16-'_key'!$A$146)<=0.005,FALSE),"✓","✗")) -> 0 | P16: =IF(ISBLANK(H16),"",IF(IFERROR(ABS(H16-'_key'!$A$147)<=0.0005,FALSE),"✓","✗")) -> 0
A17: CSM-02 | J17: =IF(ISBLANK(B17),"",IF(IFERROR(EXACT(B17,'_key'!$A$148),FALSE),"✓","✗")) -> 0 | K17: =IF(ISBLANK(C17),"",IF(IFERROR(ABS(C17-'_key'!$A$149)<=0.005,FALSE),"✓","✗")) -> 0 | L17: =IF(ISBLANK(D17),"",IF(IFERROR(ABS(D17-'_key'!$A$150)<=0.005,FALSE),"✓","✗")) -> 0 | M17: =IF(ISBLANK(E17),"",IF(IFERROR(ABS(E17-'_key'!$A$151)<=0.005,FALSE),"✓","✗")) -> 0 | N17: =IF(ISBLANK(F17),"",IF(IFERROR(ABS(F17-'_key'!$A$152)<=0.005,FALSE),"✓","✗")) -> 0 | O17: =IF(ISBLANK(G17),"",IF(IFERROR(ABS(G17-'_key'!$A$153)<=0.005,FALSE),"✓","✗")) -> 0 | P17: =IF(ISBLANK(H17),"",IF(IFERROR(ABS(H17-'_key'!$A$154)<=0.0005,FALSE),"✓","✗")) -> 0
A18: CSM-03 | J18: =IF(ISBLANK(B18),"",IF(IFERROR(EXACT(B18,'_key'!$A$155),FALSE),"✓","✗")) -> 0 | K18: =IF(ISBLANK(C18),"",IF(IFERROR(ABS(C18-'_key'!$A$156)<=0.005,FALSE),"✓","✗")) -> 0 | L18: =IF(ISBLANK(D18),"",IF(IFERROR(ABS(D18-'_key'!$A$157)<=0.005,FALSE),"✓","✗")) -> 0 | M18: =IF(ISBLANK(E18),"",IF(IFERROR(ABS(E18-'_key'!$A$158)<=0.005,FALSE),"✓","✗")) -> 0 | N18: =IF(ISBLANK(F18),"",IF(IFERROR(ABS(F18-'_key'!$A$159)<=0.005,FALSE),"✓","✗")) -> 0 | O18: =IF(ISBLANK(G18),"",IF(IFERROR(ABS(G18-'_key'!$A$160)<=0.005,FALSE),"✓","✗")) -> 0 | P18: =IF(ISBLANK(H18),"",IF(IFERROR(ABS(H18-'_key'!$A$161)<=0.0005,FALSE),"✓","✗")) -> 0
A19: CSM-04 | J19: =IF(ISBLANK(B19),"",IF(IFERROR(EXACT(B19,'_key'!$A$162),FALSE),"✓","✗")) -> 0 | K19: =IF(ISBLANK(C19),"",IF(IFERROR(ABS(C19-'_key'!$A$163)<=0.005,FALSE),"✓","✗")) -> 0 | L19: =IF(ISBLANK(D19),"",IF(IFERROR(ABS(D19-'_key'!$A$164)<=0.005,FALSE),"✓","✗")) -> 0 | M19: =IF(ISBLANK(E19),"",IF(IFERROR(ABS(E19-'_key'!$A$165)<=0.005,FALSE),"✓","✗")) -> 0 | N19: =IF(ISBLANK(F19),"",IF(IFERROR(ABS(F19-'_key'!$A$166)<=0.005,FALSE),"✓","✗")) -> 0 | O19: =IF(ISBLANK(G19),"",IF(IFERROR(ABS(G19-'_key'!$A$167)<=0.005,FALSE),"✓","✗")) -> 0 | P19: =IF(ISBLANK(H19),"",IF(IFERROR(ABS(H19-'_key'!$A$168)<=0.0005,FALSE),"✓","✗")) -> 0
A20: CSM-05 | J20: =IF(ISBLANK(B20),"",IF(IFERROR(EXACT(B20,'_key'!$A$169),FALSE),"✓","✗")) -> 0 | K20: =IF(ISBLANK(C20),"",IF(IFERROR(ABS(C20-'_key'!$A$170)<=0.005,FALSE),"✓","✗")) -> 0 | L20: =IF(ISBLANK(D20),"",IF(IFERROR(ABS(D20-'_key'!$A$171)<=0.005,FALSE),"✓","✗")) -> 0 | M20: =IF(ISBLANK(E20),"",IF(IFERROR(ABS(E20-'_key'!$A$172)<=0.005,FALSE),"✓","✗")) -> 0 | N20: =IF(ISBLANK(F20),"",IF(IFERROR(ABS(F20-'_key'!$A$173)<=0.005,FALSE),"✓","✗")) -> 0 | O20: =IF(ISBLANK(G20),"",IF(IFERROR(ABS(G20-'_key'!$A$174)<=0.005,FALSE),"✓","✗")) -> 0 | P20: =IF(ISBLANK(H20),"",IF(IFERROR(ABS(H20-'_key'!$A$175)<=0.0005,FALSE),"✓","✗")) -> 0
A21: CSM-06 | J21: =IF(ISBLANK(B21),"",IF(IFERROR(EXACT(B21,'_key'!$A$176),FALSE),"✓","✗")) -> 0 | K21: =IF(ISBLANK(C21),"",IF(IFERROR(ABS(C21-'_key'!$A$177)<=0.005,FALSE),"✓","✗")) -> 0 | L21: =IF(ISBLANK(D21),"",IF(IFERROR(ABS(D21-'_key'!$A$178)<=0.005,FALSE),"✓","✗")) -> 0 | M21: =IF(ISBLANK(E21),"",IF(IFERROR(ABS(E21-'_key'!$A$179)<=0.005,FALSE),"✓","✗")) -> 0 | N21: =IF(ISBLANK(F21),"",IF(IFERROR(ABS(F21-'_key'!$A$180)<=0.005,FALSE),"✓","✗")) -> 0 | O21: =IF(ISBLANK(G21),"",IF(IFERROR(ABS(G21-'_key'!$A$181)<=0.005,FALSE),"✓","✗")) -> 0 | P21: =IF(ISBLANK(H21),"",IF(IFERROR(ABS(H21-'_key'!$A$182)<=0.0005,FALSE),"✓","✗")) -> 0
A22: CSM-07 | J22: =IF(ISBLANK(B22),"",IF(IFERROR(EXACT(B22,'_key'!$A$183),FALSE),"✓","✗")) -> 0 | K22: =IF(ISBLANK(C22),"",IF(IFERROR(ABS(C22-'_key'!$A$184)<=0.005,FALSE),"✓","✗")) -> 0 | L22: =IF(ISBLANK(D22),"",IF(IFERROR(ABS(D22-'_key'!$A$185)<=0.005,FALSE),"✓","✗")) -> 0 | M22: =IF(ISBLANK(E22),"",IF(IFERROR(ABS(E22-'_key'!$A$186)<=0.005,FALSE),"✓","✗")) -> 0 | N22: =IF(ISBLANK(F22),"",IF(IFERROR(ABS(F22-'_key'!$A$187)<=0.005,FALSE),"✓","✗")) -> 0 | O22: =IF(ISBLANK(G22),"",IF(IFERROR(ABS(G22-'_key'!$A$188)<=0.005,FALSE),"✓","✗")) -> 0 | P22: =IF(ISBLANK(H22),"",IF(IFERROR(ABS(H22-'_key'!$A$189)<=0.0005,FALSE),"✓","✗")) -> 0
A23: CSM-08 | J23: =IF(ISBLANK(B23),"",IF(IFERROR(EXACT(B23,'_key'!$A$190),FALSE),"✓","✗")) -> 0 | K23: =IF(ISBLANK(C23),"",IF(IFERROR(ABS(C23-'_key'!$A$191)<=0.005,FALSE),"✓","✗")) -> 0 | L23: =IF(ISBLANK(D23),"",IF(IFERROR(ABS(D23-'_key'!$A$192)<=0.005,FALSE),"✓","✗")) -> 0 | M23: =IF(ISBLANK(E23),"",IF(IFERROR(ABS(E23-'_key'!$A$193)<=0.005,FALSE),"✓","✗")) -> 0 | N23: =IF(ISBLANK(F23),"",IF(IFERROR(ABS(F23-'_key'!$A$194)<=0.005,FALSE),"✓","✗")) -> 0 | O23: =IF(ISBLANK(G23),"",IF(IFERROR(ABS(G23-'_key'!$A$195)<=0.005,FALSE),"✓","✗")) -> 0 | P23: =IF(ISBLANK(H23),"",IF(IFERROR(ABS(H23-'_key'!$A$196)<=0.0005,FALSE),"✓","✗")) -> 0
A26: 3) Soporte por prioridad (todos los tickets del año)
A27: Priority | B27: Total tickets | C27: Abiertos | D27: % abiertos | E27: Días prom. de resolución | F27: CSAT promedio | J27: ✓B | K27: ✓C | L27: ✓D | M27: ✓E | N27: ✓F
A28: Dado | B28: COUNTIFS | C28: COUNTIFS con ClosedDate = "" (vacío) | D28: C / B | E28: SUMPRODUCT((Priority=A)*(ClosedDate<>"")*(ClosedDate-OpenedDate)) / COUNTIFS(..., ClosedDate, "<>") | F28: AVERAGEIFS (ignora vacíos) + IFERROR
A29: P1 | J29: =IF(ISBLANK(B29),"",IF(IFERROR(ABS(B29-'_key'!$A$197)<=0.005,FALSE),"✓","✗")) -> 0 | K29: =IF(ISBLANK(C29),"",IF(IFERROR(ABS(C29-'_key'!$A$198)<=0.005,FALSE),"✓","✗")) -> 0 | L29: =IF(ISBLANK(D29),"",IF(IFERROR(ABS(D29-'_key'!$A$199)<=0.0005,FALSE),"✓","✗")) -> 0 | M29: =IF(ISBLANK(E29),"",IF(IFERROR(ABS(E29-'_key'!$A$200)<=0.05,FALSE),"✓","✗")) -> 0 | N29: =IF(ISBLANK(F29),"",IF(IFERROR(ABS(F29-'_key'!$A$201)<=0.005,FALSE),"✓","✗")) -> 0
A30: P2 | J30: =IF(ISBLANK(B30),"",IF(IFERROR(ABS(B30-'_key'!$A$202)<=0.005,FALSE),"✓","✗")) -> 0 | K30: =IF(ISBLANK(C30),"",IF(IFERROR(ABS(C30-'_key'!$A$203)<=0.005,FALSE),"✓","✗")) -> 0 | L30: =IF(ISBLANK(D30),"",IF(IFERROR(ABS(D30-'_key'!$A$204)<=0.0005,FALSE),"✓","✗")) -> 0 | M30: =IF(ISBLANK(E30),"",IF(IFERROR(ABS(E30-'_key'!$A$205)<=0.05,FALSE),"✓","✗")) -> 0 | N30: =IF(ISBLANK(F30),"",IF(IFERROR(ABS(F30-'_key'!$A$206)<=0.005,FALSE),"✓","✗")) -> 0
A31: P3 | J31: =IF(ISBLANK(B31),"",IF(IFERROR(ABS(B31-'_key'!$A$207)<=0.005,FALSE),"✓","✗")) -> 0 | K31: =IF(ISBLANK(C31),"",IF(IFERROR(ABS(C31-'_key'!$A$208)<=0.005,FALSE),"✓","✗")) -> 0 | L31: =IF(ISBLANK(D31),"",IF(IFERROR(ABS(D31-'_key'!$A$209)<=0.0005,FALSE),"✓","✗")) -> 0 | M31: =IF(ISBLANK(E31),"",IF(IFERROR(ABS(E31-'_key'!$A$210)<=0.05,FALSE),"✓","✗")) -> 0 | N31: =IF(ISBLANK(F31),"",IF(IFERROR(ABS(F31-'_key'!$A$211)<=0.005,FALSE),"✓","✗")) -> 0
A32: P4 | J32: =IF(ISBLANK(B32),"",IF(IFERROR(ABS(B32-'_key'!$A$212)<=0.005,FALSE),"✓","✗")) -> 0 | K32: =IF(ISBLANK(C32),"",IF(IFERROR(ABS(C32-'_key'!$A$213)<=0.005,FALSE),"✓","✗")) -> 0 | L32: =IF(ISBLANK(D32),"",IF(IFERROR(ABS(D32-'_key'!$A$214)<=0.0005,FALSE),"✓","✗")) -> 0 | M32: =IF(ISBLANK(E32),"",IF(IFERROR(ABS(E32-'_key'!$A$215)<=0.05,FALSE),"✓","✗")) -> 0 | N32: =IF(ISBLANK(F32),"",IF(IFERROR(ABS(F32-'_key'!$A$216)<=0.005,FALSE),"✓","✗")) -> 0
A35: 4) NPS global (todas las respuestas)
A36: Métrica | B36: Valor | C36: Pista
A37: Promotores (9-10) | C37: COUNTIF >=9 | J37: =IF(ISBLANK(B37),"",IF(IFERROR(ABS(B37-'_key'!$A$217)<=0.05,FALSE),"✓","✗")) -> 0
A38: Pasivos (7-8) | C38: COUNTIFS con 2 criterios sobre la misma columna | J38: =IF(ISBLANK(B38),"",IF(IFERROR(ABS(B38-'_key'!$A$218)<=0.05,FALSE),"✓","✗")) -> 0
A39: Detractores (0-6) | C39: COUNTIF <=6 | J39: =IF(ISBLANK(B39),"",IF(IFERROR(ABS(B39-'_key'!$A$219)<=0.05,FALSE),"✓","✗")) -> 0
A40: Total respuestas | C40: SUM | J40: =IF(ISBLANK(B40),"",IF(IFERROR(ABS(B40-'_key'!$A$220)<=0.05,FALSE),"✓","✗")) -> 0
A41: NPS | C41: (%Promotores − %Detractores) × 100. Rango −100 a 100 | J41: =IF(ISBLANK(B41),"",IF(IFERROR(ABS(B41-'_key'!$A$221)<=0.05,FALSE),"✓","✗")) -> 0

Sheet E3_Health_Score
A1: E3 · Customer Health Score
A2: Objetivo: calcular para cada cuenta activa un health score de 0-100 combinando adopción (uso de licencias), tendencia de uso, tickets críticos abiertos y NPS; clasificar Green/Yellow/Red y marcar las cuentas en rojo que renuevan en ≤180 días. Los pesos están en la fila 4 (deben sumar 100%).
A3: Contexto: es lo que pide la vacante — 'build and refine health-score and KPI frameworks'. En la entrevista explica POR QUÉ elegiste cada métrica y peso, y qué validarías con los CSMs (¿las cuentas Red realmente están en riesgo?).
N4: Pesos → | O4: 0.35 | P4: 0.25 | Q4: 0.2 | R4: 0.2 | S4: =SUM(O4:R4) -> 1 | T4: =IF(ROUND(S4,4)=1,"Pesos OK","Los pesos deben sumar 100%") -> Pesos OK | AF4: Resumen (usa los nombres definidos HS_Cat, HS_ARR, ...)
A6: AccountID | B6: AccountName | C6: Segment | D6: CSM_ID | E6: ARR_USD | F6: LicensedSeats | G6: ActiveUsers (LastMonth) | H6: Seat Utilization | I6: Logins últimos 3m | J6: Logins 3m previos | K6: Tendencia uso % | L6: Tickets P1/P2 abiertos | M6: NPS prom. 12m | N6: Días a renovación | O6: Score Adopción | P6: Score Tendencia | Q6: Score Soporte | R6: Score NPS | S6: HEALTH SCORE | T6: Categoría | U6: Alerta | V6: Rank (1 = peor) | X6: ✓H | Y6: ✓K | Z6: ✓L | AA6: ✓M | AB6: ✓S | AC6: ✓T | AD6: ✓V | AF6: Categoría | AG6: # Cuentas | AH6: ARR | AI6: Chk
A7: Dado | B7: XLOOKUP | C7: XLOOKUP | D7: XLOOKUP | E7: XLOOKUP | F7: XLOOKUP | G7: SUMIFS(tbl_Usage[ActiveUsers], ...[AccountID], A8, ...[Month], LastMonth) | H7: IFERROR(ROUND(G8/F8, 4), 0) | I7: SUMIFS(...[Logins], ..., [Month], ">="&EDATE(LastMonth,-2)) | J7: Meses −5 a −3: ">="&EDATE(LastMonth,-5) y "<"&EDATE(LastMonth,-2) | K7: IFERROR(ROUND(I8/J8-1, 4), 0) | L7: SUM(COUNTIFS(...[AccountID],A8, ...[ClosedDate],"", ...[Priority],{"P1","P2"})) | M7: IFERROR(AVERAGEIFS(tbl_NPS[Score], ..., [ResponseDate], ">"&EDATE(AsOfDate,-12)), "") | N7: XLOOKUP(RenewalDate) − AsOfDate | O7: IFS: ≥80%→100, ≥60%→75, ≥40%→50, ≥20%→25, si no 0 | P7: IFS: ≥10%→100, ≥0%→75, ≥−10%→50, ≥−25%→25, si no 0 | Q7: IFS: 0→100, 1→60, ≤3→30, si no 0 | R7: Sin NPS ("")→50; IFS: ≥9→100, ≥7→70, ≥5→40, si no 10 | S7: ROUND(SUMPRODUCT(O8:R8, $O$4:$R$4), 1) | T7: IFS: ≥75 Green, ≥50 Yellow, si no Red | U7: Red y renovación ≤180 días → "⚠ Riesgo renovación", si no "" | V7: RANK.EQ(S8, $S$8:$S$n, 1) | AF7: Green | AI7: =IF(ISBLANK(AG7),"",IF(IFERROR(ABS(AG7-'_key'!$A$1188)<=0.005,FALSE),"✓","✗")) -> 0
A8: ACC-0002 | X8: =IF(ISBLANK(H8),"",IF(IFERROR(ABS(H8-'_key'!$A$222)<=5e-05,FALSE),"✓","✗")) -> 0 | Y8: =IF(ISBLANK(K8),"",IF(IFERROR(ABS(K8-'_key'!$A$223)<=5e-05,FALSE),"✓","✗")) -> 0 | Z8: =IF(ISBLANK(L8),"",IF(IFERROR(ABS(L8-'_key'!$A$224)<=0.005,FALSE),"✓","✗")) -> 0 | AA8: =IF(ISBLANK(M8),"",IF(IFERROR(ABS(M8-'_key'!$A$225)<=0.005,FALSE),"✓","✗")) -> 0 | AB8: =IF(ISBLANK(S8),"",IF(IFERROR(ABS(S8-'_key'!$A$226)<=0.01,FALSE),"✓","✗")) -> 0 | AC8: =IF(ISBLANK(T8),"",IF(IFERROR(EXACT(T8,'_key'!$A$227),FALSE),"✓","✗")) -> 0 | AD8: =IF(ISBLANK(V8),"",IF(IFERROR(ABS(V8-'_key'!$A$228)<=0.005,FALSE),"✓","✗")) -> 0 | AF8: Yellow | AI8: =IF(ISBLANK(AG8),"",IF(IFERROR(ABS(AG8-'_key'!$A$1190)<=0.005,FALSE),"✓","✗")) -> 0
A9: ACC-0003 | X9: =IF(ISBLANK(H9),"",IF(IFERROR(ABS(H9-'_key'!$A$229)<=5e-05,FALSE),"✓","✗")) -> 0 | Y9: =IF(ISBLANK(K9),"",IF(IFERROR(ABS(K9-'_key'!$A$230)<=5e-05,FALSE),"✓","✗")) -> 0 | Z9: =IF(ISBLANK(L9),"",IF(IFERROR(ABS(L9-'_key'!$A$231)<=0.005,FALSE),"✓","✗")) -> 0 | AA9: =IF(ISBLANK(M9),"",IF(IFERROR(ABS(M9-'_key'!$A$232)<=0.005,FALSE),"✓","✗")) -> 0 | AB9: =IF(ISBLANK(S9),"",IF(IFERROR(ABS(S9-'_key'!$A$233)<=0.01,FALSE),"✓","✗")) -> 0 | AC9: =IF(ISBLANK(T9),"",IF(IFERROR(EXACT(T9,'_key'!$A$234),FALSE),"✓","✗")) -> 0 | AD9: =IF(ISBLANK(V9),"",IF(IFERROR(ABS(V9-'_key'!$A$235)<=0.005,FALSE),"✓","✗")) -> 0 | AF9: Red | AI9: =IF(ISBLANK(AG9),"",IF(IFERROR(ABS(AG9-'_key'!$A$1192)<=0.005,FALSE),"✓","✗")) -> 0
A10: ACC-0004 | X10: =IF(ISBLANK(H10),"",IF(IFERROR(ABS(H10-'_key'!$A$236)<=5e-05,FALSE),"✓","✗")) -> 0 | Y10: =IF(ISBLANK(K10),"",IF(IFERROR(ABS(K10-'_key'!$A$237)<=5e-05,FALSE),"✓","✗")) -> 0 | Z10: =IF(ISBLANK(L10),"",IF(IFERROR(ABS(L10-'_key'!$A$238)<=0.005,FALSE),"✓","✗")) -> 0 | AA10: =IF(ISBLANK(M10),"",IF(IFERROR(ABS(M10-'_key'!$A$239)<=0.005,FALSE),"✓","✗")) -> 0 | AB10: =IF(ISBLANK(S10),"",IF(IFERROR(ABS(S10-'_key'!$A$240)<=0.01,FALSE),"✓","✗")) -> 0 | AC10: =IF(ISBLANK(T10),"",IF(IFERROR(EXACT(T10,'_key'!$A$241),FALSE),"✓","✗")) -> 0 | AD10: =IF(ISBLANK(V10),"",IF(IFERROR(ABS(V10-'_key'!$A$242)<=0.005,FALSE),"✓","✗")) -> 0
A11: ACC-0005 | X11: =IF(ISBLANK(H11),"",IF(IFERROR(ABS(H11-'_key'!$A$243)<=5e-05,FALSE),"✓","✗")) -> 0 | Y11: =IF(ISBLANK(K11),"",IF(IFERROR(ABS(K11-'_key'!$A$244)<=5e-05,FALSE),"✓","✗")) -> 0 | Z11: =IF(ISBLANK(L11),"",IF(IFERROR(ABS(L11-'_key'!$A$245)<=0.005,FALSE),"✓","✗")) -> 0 | AA11: =IF(ISBLANK(M11),"",IF(IFERROR(ABS(M11-'_key'!$A$246)<=0.005,FALSE),"✓","✗")) -> 0 | AB11: =IF(ISBLANK(S11),"",IF(IFERROR(ABS(S11-'_key'!$A$247)<=0.01,FALSE),"✓","✗")) -> 0 | AC11: =IF(ISBLANK(T11),"",IF(IFERROR(EXACT(T11,'_key'!$A$248),FALSE),"✓","✗")) -> 0 | AD11: =IF(ISBLANK(V11),"",IF(IFERROR(ABS(V11-'_key'!$A$249)<=0.005,FALSE),"✓","✗")) -> 0 | AF11: Health score promedio | AI11: =IF(ISBLANK(AH11),"",IF(IFERROR(ABS(AH11-'_key'!$A$1194)<=0.05,FALSE),"✓","✗")) -> 0
A12: ACC-0006 | X12: =IF(ISBLANK(H12),"",IF(IFERROR(ABS(H12-'_key'!$A$250)<=5e-05,FALSE),"✓","✗")) -> 0 | Y12: =IF(ISBLANK(K12),"",IF(IFERROR(ABS(K12-'_key'!$A$251)<=5e-05,FALSE),"✓","✗")) -> 0 | Z12: =IF(ISBLANK(L12),"",IF(IFERROR(ABS(L12-'_key'!$A$252)<=0.005,FALSE),"✓","✗")) -> 0 | AA12: =IF(ISBLANK(M12),"",IF(IFERROR(ABS(M12-'_key'!$A$253)<=0.005,FALSE),"✓","✗")) -> 0 | AB12: =IF(ISBLANK(S12),"",IF(IFERROR(ABS(S12-'_key'!$A$254)<=0.01,FALSE),"✓","✗")) -> 0 | AC12: =IF(ISBLANK(T12),"",IF(IFERROR(EXACT(T12,'_key'!$A$255),FALSE),"✓","✗")) -> 0 | AD12: =IF(ISBLANK(V12),"",IF(IFERROR(ABS(V12-'_key'!$A$256)<=0.005,FALSE),"✓","✗")) -> 0 | AF12: ARR ponderado por health (prom.) | AI12: =IF(ISBLANK(AH12),"",IF(IFERROR(ABS(AH12-'_key'!$A$1195)<=0.05,FALSE),"✓","✗")) -> 0
A13: ACC-0007 | X13: =IF(ISBLANK(H13),"",IF(IFERROR(ABS(H13-'_key'!$A$257)<=5e-05,FALSE),"✓","✗")) -> 0 | Y13: =IF(ISBLANK(K13),"",IF(IFERROR(ABS(K13-'_key'!$A$258)<=5e-05,FALSE),"✓","✗")) -> 0 | Z13: =IF(ISBLANK(L13),"",IF(IFERROR(ABS(L13-'_key'!$A$259)<=0.005,FALSE),"✓","✗")) -> 0 | AA13: =IF(ISBLANK(M13),"",IF(IFERROR(ABS(M13-'_key'!$A$260)<=0.005,FALSE),"✓","✗")) -> 0 | AB13: =IF(ISBLANK(S13),"",IF(IFERROR(ABS(S13-'_key'!$A$261)<=0.01,FALSE),"✓","✗")) -> 0 | AC13: =IF(ISBLANK(T13),"",IF(IFERROR(EXACT(T13,'_key'!$A$262),FALSE),"✓","✗")) -> 0 | AD13: =IF(ISBLANK(V13),"",IF(IFERROR(ABS(V13-'_key'!$A$263)<=0.005,FALSE),"✓","✗")) -> 0 | AF13: # Cuentas con alerta de renovación | AI13: =IF(ISBLANK(AH13),"",IF(IFERROR(ABS(AH13-'_key'!$A$1196)<=0.05,FALSE),"✓","✗")) -> 0
A14: ACC-0008 | X14: =IF(ISBLANK(H14),"",IF(IFERROR(ABS(H14-'_key'!$A$264)<=5e-05,FALSE),"✓","✗")) -> 0 | Y14: =IF(ISBLANK(K14),"",IF(IFERROR(ABS(K14-'_key'!$A$265)<=5e-05,FALSE),"✓","✗")) -> 0 | Z14: =IF(ISBLANK(L14),"",IF(IFERROR(ABS(L14-'_key'!$A$266)<=0.005,FALSE),"✓","✗")) -> 0 | AA14: =IF(ISBLANK(M14),"",IF(IFERROR(EXACT(M14,'_key'!$A$267),FALSE),"✓","✗")) -> 0 | AB14: =IF(ISBLANK(S14),"",IF(IFERROR(ABS(S14-'_key'!$A$268)<=0.01,FALSE),"✓","✗")) -> 0 | AC14: =IF(ISBLANK(T14),"",IF(IFERROR(EXACT(T14,'_key'!$A$269),FALSE),"✓","✗")) -> 0 | AD14: =IF(ISBLANK(V14),"",IF(IFERROR(ABS(V14-'_key'!$A$270)<=0.005,FALSE),"✓","✗")) -> 0 | AF14: ARR en riesgo (Red, ≤180 días) | AI14: =IF(ISBLANK(AH14),"",IF(IFERROR(ABS(AH14-'_key'!$A$1197)<=0.05,FALSE),"✓","✗")) -> 0
A15: ACC-0009 | X15: =IF(ISBLANK(H15),"",IF(IFERROR(ABS(H15-'_key'!$A$271)<=5e-05,FALSE),"✓","✗")) -> 0 | Y15: =IF(ISBLANK(K15),"",IF(IFERROR(ABS(K15-'_key'!$A$272)<=5e-05,FALSE),"✓","✗")) -> 0 | Z15: =IF(ISBLANK(L15),"",IF(IFERROR(ABS(L15-'_key'!$A$273)<=0.005,FALSE),"✓","✗")) -> 0 | AA15: =IF(ISBLANK(M15),"",IF(IFERROR(ABS(M15-'_key'!$A$274)<=0.005,FALSE),"✓","✗")) -> 0 | AB15: =IF(ISBLANK(S15),"",IF(IFERROR(ABS(S15-'_key'!$A$275)<=0.01,FALSE),"✓","✗")) -> 0 | AC15: =IF(ISBLANK(T15),"",IF(IFERROR(EXACT(T15,'_key'!$A$276),FALSE),"✓","✗")) -> 0 | AD15: =IF(ISBLANK(V15),"",IF(IFERROR(ABS(V15-'_key'!$A$277)<=0.005,FALSE),"✓","✗")) -> 0
A16: ACC-0010 | X16: =IF(ISBLANK(H16),"",IF(IFERROR(ABS(H16-'_key'!$A$278)<=5e-05,FALSE),"✓","✗")) -> 0 | Y16: =IF(ISBLANK(K16),"",IF(IFERROR(ABS(K16-'_key'!$A$279)<=5e-05,FALSE),"✓","✗")) -> 0 | Z16: =IF(ISBLANK(L16),"",IF(IFERROR(ABS(L16-'_key'!$A$280)<=0.005,FALSE),"✓","✗")) -> 0 | AA16: =IF(ISBLANK(M16),"",IF(IFERROR(ABS(M16-'_key'!$A$281)<=0.005,FALSE),"✓","✗")) -> 0 | AB16: =IF(ISBLANK(S16),"",IF(IFERROR(ABS(S16-'_key'!$A$282)<=0.01,FALSE),"✓","✗")) -> 0 | AC16: =IF(ISBLANK(T16),"",IF(IFERROR(EXACT(T16,'_key'!$A$283),FALSE),"✓","✗")) -> 0 | AD16: =IF(ISBLANK(V16),"",IF(IFERROR(ABS(V16-'_key'!$A$284)<=0.005,FALSE),"✓","✗")) -> 0 | AF16: ✓ de la columna ARR (G/Y/R) → | AI16: =IF(ISBLANK(AH7),"",IF(IFERROR(ABS(AH7-'_key'!$A$1189)<=0.005,FALSE),"✓","✗")) -> 0
A17: ACC-0011 | X17: =IF(ISBLANK(H17),"",IF(IFERROR(ABS(H17-'_key'!$A$285)<=5e-05,FALSE),"✓","✗")) -> 0 | Y17: =IF(ISBLANK(K17),"",IF(IFERROR(ABS(K17-'_key'!$A$286)<=5e-05,FALSE),"✓","✗")) -> 0 | Z17: =IF(ISBLANK(L17),"",IF(IFERROR(ABS(L17-'_key'!$A$287)<=0.005,FALSE),"✓","✗")) -> 0 | AA17: =IF(ISBLANK(M17),"",IF(IFERROR(EXACT(M17,'_key'!$A$288),FALSE),"✓","✗")) -> 0 | AB17: =IF(ISBLANK(S17),"",IF(IFERROR(ABS(S17-'_key'!$A$289)<=0.01,FALSE),"✓","✗")) -> 0 | AC17: =IF(ISBLANK(T17),"",IF(IFERROR(EXACT(T17,'_key'!$A$290),FALSE),"✓","✗")) -> 0 | AD17: =IF(ISBLANK(V17),"",IF(IFERROR(ABS(V17-'_key'!$A$291)<=0.005,FALSE),"✓","✗")) -> 0 | AI17: =IF(ISBLANK(AH8),"",IF(IFERROR(ABS(AH8-'_key'!$A$1191)<=0.005,FALSE),"✓","✗")) -> 0
A18: ACC-0012 | X18: =IF(ISBLANK(H18),"",IF(IFERROR(ABS(H18-'_key'!$A$292)<=5e-05,FALSE),"✓","✗")) -> 0 | Y18: =IF(ISBLANK(K18),"",IF(IFERROR(ABS(K18-'_key'!$A$293)<=5e-05,FALSE),"✓","✗")) -> 0 | Z18: =IF(ISBLANK(L18),"",IF(IFERROR(ABS(L18-'_key'!$A$294)<=0.005,FALSE),"✓","✗")) -> 0 | AA18: =IF(ISBLANK(M18),"",IF(IFERROR(ABS(M18-'_key'!$A$295)<=0.005,FALSE),"✓","✗")) -> 0 | AB18: =IF(ISBLANK(S18),"",IF(IFERROR(ABS(S18-'_key'!$A$296)<=0.01,FALSE),"✓","✗")) -> 0 | AC18: =IF(ISBLANK(T18),"",IF(IFERROR(EXACT(T18,'_key'!$A$297),FALSE),"✓","✗")) -> 0 | AD18: =IF(ISBLANK(V18),"",IF(IFERROR(ABS(V18-'_key'!$A$298)<=0.005,FALSE),"✓","✗")) -> 0 | AI18: =IF(ISBLANK(AH9),"",IF(IFERROR(ABS(AH9-'_key'!$A$1193)<=0.005,FALSE),"✓","✗")) -> 0
A19: ACC-0013 | X19: =IF(ISBLANK(H19),"",IF(IFERROR(ABS(H19-'_key'!$A$299)<=5e-05,FALSE),"✓","✗")) -> 0 | Y19: =IF(ISBLANK(K19),"",IF(IFERROR(ABS(K19-'_key'!$A$300)<=5e-05,FALSE),"✓","✗")) -> 0 | Z19: =IF(ISBLANK(L19),"",IF(IFERROR(ABS(L19-'_key'!$A$301)<=0.005,FALSE),"✓","✗")) -> 0 | AA19: =IF(ISBLANK(M19),"",IF(IFERROR(EXACT(M19,'_key'!$A$302),FALSE),"✓","✗")) -> 0 | AB19: =IF(ISBLANK(S19),"",IF(IFERROR(ABS(S19-'_key'!$A$303)<=0.01,FALSE),"✓","✗")) -> 0 | AC19: =IF(ISBLANK(T19),"",IF(IFERROR(EXACT(T19,'_key'!$A$304),FALSE),"✓","✗")) -> 0 | AD19: =IF(ISBLANK(V19),"",IF(IFERROR(ABS(V19-'_key'!$A$305)<=0.005,FALSE),"✓","✗")) -> 0
A20: ACC-0014 | X20: =IF(ISBLANK(H20),"",IF(IFERROR(ABS(H20-'_key'!$A$306)<=5e-05,FALSE),"✓","✗")) -> 0 | Y20: =IF(ISBLANK(K20),"",IF(IFERROR(ABS(K20-'_key'!$A$307)<=5e-05,FALSE),"✓","✗")) -> 0 | Z20: =IF(ISBLANK(L20),"",IF(IFERROR(ABS(L20-'_key'!$A$308)<=0.005,FALSE),"✓","✗")) -> 0 | AA20: =IF(ISBLANK(M20),"",IF(IFERROR(ABS(M20-'_key'!$A$309)<=0.005,FALSE),"✓","✗")) -> 0 | AB20: =IF(ISBLANK(S20),"",IF(IFERROR(ABS(S20-'_key'!$A$310)<=0.01,FALSE),"✓","✗")) -> 0 | AC20: =IF(ISBLANK(T20),"",IF(IFERROR(EXACT(T20,'_key'!$A$311),FALSE),"✓","✗")) -> 0 | AD20: =IF(ISBLANK(V20),"",IF(IFERROR(ABS(V20-'_key'!$A$312)<=0.005,FALSE),"✓","✗")) -> 0
A21: ACC-0015 | X21: =IF(ISBLANK(H21),"",IF(IFERROR(ABS(H21-'_key'!$A$313)<=5e-05,FALSE),"✓","✗")) -> 0 | Y21: =IF(ISBLANK(K21),"",IF(IFERROR(ABS(K21-'_key'!$A$314)<=5e-05,FALSE),"✓","✗")) -> 0 | Z21: =IF(ISBLANK(L21),"",IF(IFERROR(ABS(L21-'_key'!$A$315)<=0.005,FALSE),"✓","✗")) -> 0 | AA21: =IF(ISBLANK(M21),"",IF(IFERROR(ABS(M21-'_key'!$A$316)<=0.005,FALSE),"✓","✗")) -> 0 | AB21: =IF(ISBLANK(S21),"",IF(IFERROR(ABS(S21-'_key'!$A$317)<=0.01,FALSE),"✓","✗")) -> 0 | AC21: =IF(ISBLANK(T21),"",IF(IFERROR(EXACT(T21,'_key'!$A$318),FALSE),"✓","✗")) -> 0 | AD21: =IF(ISBLANK(V21),"",IF(IFERROR(ABS(V21-'_key'!$A$319)<=0.005,FALSE),"✓","✗")) -> 0
A22: ACC-0016 | X22: =IF(ISBLANK(H22),"",IF(IFERROR(ABS(H22-'_key'!$A$320)<=5e-05,FALSE),"✓","✗")) -> 0 | Y22: =IF(ISBLANK(K22),"",IF(IFERROR(ABS(K22-'_key'!$A$321)<=5e-05,FALSE),"✓","✗")) -> 0 | Z22: =IF(ISBLANK(L22),"",IF(IFERROR(ABS(L22-'_key'!$A$322)<=0.005,FALSE),"✓","✗")) -> 0 | AA22: =IF(ISBLANK(M22),"",IF(IFERROR(ABS(M22-'_key'!$A$323)<=0.005,FALSE),"✓","✗")) -> 0 | AB22: =IF(ISBLANK(S22),"",IF(IFERROR(ABS(S22-'_key'!$A$324)<=0.01,FALSE),"✓","✗")) -> 0 | AC22: =IF(ISBLANK(T22),"",IF(IFERROR(EXACT(T22,'_key'!$A$325),FALSE),"✓","✗")) -> 0 | AD22: =IF(ISBLANK(V22),"",IF(IFERROR(ABS(V22-'_key'!$A$326)<=0.005,FALSE),"✓","✗")) -> 0
A23: ACC-0017 | X23: =IF(ISBLANK(H23),"",IF(IFERROR(ABS(H23-'_key'!$A$327)<=5e-05,FALSE),"✓","✗")) -> 0 | Y23: =IF(ISBLANK(K23),"",IF(IFERROR(ABS(K23-'_key'!$A$328)<=5e-05,FALSE),"✓","✗")) -> 0 | Z23: =IF(ISBLANK(L23),"",IF(IFERROR(ABS(L23-'_key'!$A$329)<=0.005,FALSE),"✓","✗")) -> 0 | AA23: =IF(ISBLANK(M23),"",IF(IFERROR(ABS(M23-'_key'!$A$330)<=0.005,FALSE),"✓","✗")) -> 0 | AB23: =IF(ISBLANK(S23),"",IF(IFERROR(ABS(S23-'_key'!$A$331)<=0.01,FALSE),"✓","✗")) -> 0 | AC23: =IF(ISBLANK(T23),"",IF(IFERROR(EXACT(T23,'_key'!$A$332),FALSE),"✓","✗")) -> 0 | AD23: =IF(ISBLANK(V23),"",IF(IFERROR(ABS(V23-'_key'!$A$333)<=0.005,FALSE),"✓","✗")) -> 0
A24: ACC-0018 | X24: =IF(ISBLANK(H24),"",IF(IFERROR(ABS(H24-'_key'!$A$334)<=5e-05,FALSE),"✓","✗")) -> 0 | Y24: =IF(ISBLANK(K24),"",IF(IFERROR(ABS(K24-'_key'!$A$335)<=5e-05,FALSE),"✓","✗")) -> 0 | Z24: =IF(ISBLANK(L24),"",IF(IFERROR(ABS(L24-'_key'!$A$336)<=0.005,FALSE),"✓","✗")) -> 0 | AA24: =IF(ISBLANK(M24),"",IF(IFERROR(ABS(M24-'_key'!$A$337)<=0.005,FALSE),"✓","✗")) -> 0 | AB24: =IF(ISBLANK(S24),"",IF(IFERROR(ABS(S24-'_key'!$A$338)<=0.01,FALSE),"✓","✗")) -> 0 | AC24: =IF(ISBLANK(T24),"",IF(IFERROR(EXACT(T24,'_key'!$A$339),FALSE),"✓","✗")) -> 0 | AD24: =IF(ISBLANK(V24),"",IF(IFERROR(ABS(V24-'_key'!$A$340)<=0.005,FALSE),"✓","✗")) -> 0
A25: ACC-0019 | X25: =IF(ISBLANK(H25),"",IF(IFERROR(ABS(H25-'_key'!$A$341)<=5e-05,FALSE),"✓","✗")) -> 0 | Y25: =IF(ISBLANK(K25),"",IF(IFERROR(ABS(K25-'_key'!$A$342)<=5e-05,FALSE),"✓","✗")) -> 0 | Z25: =IF(ISBLANK(L25),"",IF(IFERROR(ABS(L25-'_key'!$A$343)<=0.005,FALSE),"✓","✗")) -> 0 | AA25: =IF(ISBLANK(M25),"",IF(IFERROR(ABS(M25-'_key'!$A$344)<=0.005,FALSE),"✓","✗")) -> 0 | AB25: =IF(ISBLANK(S25),"",IF(IFERROR(ABS(S25-'_key'!$A$345)<=0.01,FALSE),"✓","✗")) -> 0 | AC25: =IF(ISBLANK(T25),"",IF(IFERROR(EXACT(T25,'_key'!$A$346),FALSE),"✓","✗")) -> 0 | AD25: =IF(ISBLANK(V25),"",IF(IFERROR(ABS(V25-'_key'!$A$347)<=0.005,FALSE),"✓","✗")) -> 0
A26: ACC-0020 | X26: =IF(ISBLANK(H26),"",IF(IFERROR(ABS(H26-'_key'!$A$348)<=5e-05,FALSE),"✓","✗")) -> 0 | Y26: =IF(ISBLANK(K26),"",IF(IFERROR(ABS(K26-'_key'!$A$349)<=5e-05,FALSE),"✓","✗")) -> 0 | Z26: =IF(ISBLANK(L26),"",IF(IFERROR(ABS(L26-'_key'!$A$350)<=0.005,FALSE),"✓","✗")) -> 0 | AA26: =IF(ISBLANK(M26),"",IF(IFERROR(EXACT(M26,'_key'!$A$351),FALSE),"✓","✗")) -> 0 | AB26: =IF(ISBLANK(S26),"",IF(IFERROR(ABS(S26-'_key'!$A$352)<=0.01,FALSE),"✓","✗")) -> 0 | AC26: =IF(ISBLANK(T26),"",IF(IFERROR(EXACT(T26,'_key'!$A$353),FALSE),"✓","✗")) -> 0 | AD26: =IF(ISBLANK(V26),"",IF(IFERROR(ABS(V26-'_key'!$A$354)<=0.005,FALSE),"✓","✗")) -> 0
A27: ACC-0021 | X27: =IF(ISBLANK(H27),"",IF(IFERROR(ABS(H27-'_key'!$A$355)<=5e-05,FALSE),"✓","✗")) -> 0 | Y27: =IF(ISBLANK(K27),"",IF(IFERROR(ABS(K27-'_key'!$A$356)<=5e-05,FALSE),"✓","✗")) -> 0 | Z27: =IF(ISBLANK(L27),"",IF(IFERROR(ABS(L27-'_key'!$A$357)<=0.005,FALSE),"✓","✗")) -> 0 | AA27: =IF(ISBLANK(M27),"",IF(IFERROR(ABS(M27-'_key'!$A$358)<=0.005,FALSE),"✓","✗")) -> 0 | AB27: =IF(ISBLANK(S27),"",IF(IFERROR(ABS(S27-'_key'!$A$359)<=0.01,FALSE),"✓","✗")) -> 0 | AC27: =IF(ISBLANK(T27),"",IF(IFERROR(EXACT(T27,'_key'!$A$360),FALSE),"✓","✗")) -> 0 | AD27: =IF(ISBLANK(V27),"",IF(IFERROR(ABS(V27-'_key'!$A$361)<=0.005,FALSE),"✓","✗")) -> 0
A28: ACC-0022 | X28: =IF(ISBLANK(H28),"",IF(IFERROR(ABS(H28-'_key'!$A$362)<=5e-05,FALSE),"✓","✗")) -> 0 | Y28: =IF(ISBLANK(K28),"",IF(IFERROR(ABS(K28-'_key'!$A$363)<=5e-05,FALSE),"✓","✗")) -> 0 | Z28: =IF(ISBLANK(L28),"",IF(IFERROR(ABS(L28-'_key'!$A$364)<=0.005,FALSE),"✓","✗")) -> 0 | AA28: =IF(ISBLANK(M28),"",IF(IFERROR(ABS(M28-'_key'!$A$365)<=0.005,FALSE),"✓","✗")) -> 0 | AB28: =IF(ISBLANK(S28),"",IF(IFERROR(ABS(S28-'_key'!$A$366)<=0.01,FALSE),"✓","✗")) -> 0 | AC28: =IF(ISBLANK(T28),"",IF(IFERROR(EXACT(T28,'_key'!$A$367),FALSE),"✓","✗")) -> 0 | AD28: =IF(ISBLANK(V28),"",IF(IFERROR(ABS(V28-'_key'!$A$368)<=0.005,FALSE),"✓","✗")) -> 0
A29: ACC-0024 | X29: =IF(ISBLANK(H29),"",IF(IFERROR(ABS(H29-'_key'!$A$369)<=5e-05,FALSE),"✓","✗")) -> 0 | Y29: =IF(ISBLANK(K29),"",IF(IFERROR(ABS(K29-'_key'!$A$370)<=5e-05,FALSE),"✓","✗")) -> 0 | Z29: =IF(ISBLANK(L29),"",IF(IFERROR(ABS(L29-'_key'!$A$371)<=0.005,FALSE),"✓","✗")) -> 0 | AA29: =IF(ISBLANK(M29),"",IF(IFERROR(ABS(M29-'_key'!$A$372)<=0.005,FALSE),"✓","✗")) -> 0 | AB29: =IF(ISBLANK(S29),"",IF(IFERROR(ABS(S29-'_key'!$A$373)<=0.01,FALSE),"✓","✗")) -> 0 | AC29: =IF(ISBLANK(T29),"",IF(IFERROR(EXACT(T29,'_key'!$A$374),FALSE),"✓","✗")) -> 0 | AD29: =IF(ISBLANK(V29),"",IF(IFERROR(ABS(V29-'_key'!$A$375)<=0.005,FALSE),"✓","✗")) -> 0
A30: ACC-0025 | X30: =IF(ISBLANK(H30),"",IF(IFERROR(ABS(H30-'_key'!$A$376)<=5e-05,FALSE),"✓","✗")) -> 0 | Y30: =IF(ISBLANK(K30),"",IF(IFERROR(ABS(K30-'_key'!$A$377)<=5e-05,FALSE),"✓","✗")) -> 0 | Z30: =IF(ISBLANK(L30),"",IF(IFERROR(ABS(L30-'_key'!$A$378)<=0.005,FALSE),"✓","✗")) -> 0 | AA30: =IF(ISBLANK(M30),"",IF(IFERROR(ABS(M30-'_key'!$A$379)<=0.005,FALSE),"✓","✗")) -> 0 | AB30: =IF(ISBLANK(S30),"",IF(IFERROR(ABS(S30-'_key'!$A$380)<=0.01,FALSE),"✓","✗")) -> 0 | AC30: =IF(ISBLANK(T30),"",IF(IFERROR(EXACT(T30,'_key'!$A$381),FALSE),"✓","✗")) -> 0 | AD30: =IF(ISBLANK(V30),"",IF(IFERROR(ABS(V30-'_key'!$A$382)<=0.005,FALSE),"✓","✗")) -> 0
A31: ACC-0026 | X31: =IF(ISBLANK(H31),"",IF(IFERROR(ABS(H31-'_key'!$A$383)<=5e-05,FALSE),"✓","✗")) -> 0 | Y31: =IF(ISBLANK(K31),"",IF(IFERROR(ABS(K31-'_key'!$A$384)<=5e-05,FALSE),"✓","✗")) -> 0 | Z31: =IF(ISBLANK(L31),"",IF(IFERROR(ABS(L31-'_key'!$A$385)<=0.005,FALSE),"✓","✗")) -> 0 | AA31: =IF(ISBLANK(M31),"",IF(IFERROR(ABS(M31-'_key'!$A$386)<=0.005,FALSE),"✓","✗")) -> 0 | AB31: =IF(ISBLANK(S31),"",IF(IFERROR(ABS(S31-'_key'!$A$387)<=0.01,FALSE),"✓","✗")) -> 0 | AC31: =IF(ISBLANK(T31),"",IF(IFERROR(EXACT(T31,'_key'!$A$388),FALSE),"✓","✗")) -> 0 | AD31: =IF(ISBLANK(V31),"",IF(IFERROR(ABS(V31-'_key'!$A$389)<=0.005,FALSE),"✓","✗")) -> 0
A32: ACC-0027 | X32: =IF(ISBLANK(H32),"",IF(IFERROR(ABS(H32-'_key'!$A$390)<=5e-05,FALSE),"✓","✗")) -> 0 | Y32: =IF(ISBLANK(K32),"",IF(IFERROR(ABS(K32-'_key'!$A$391)<=5e-05,FALSE),"✓","✗")) -> 0 | Z32: =IF(ISBLANK(L32),"",IF(IFERROR(ABS(L32-'_key'!$A$392)<=0.005,FALSE),"✓","✗")) -> 0 | AA32: =IF(ISBLANK(M32),"",IF(IFERROR(EXACT(M32,'_key'!$A$393),FALSE),"✓","✗")) -> 0 | AB32: =IF(ISBLANK(S32),"",IF(IFERROR(ABS(S32-'_key'!$A$394)<=0.01,FALSE),"✓","✗")) -> 0 | AC32: =IF(ISBLANK(T32),"",IF(IFERROR(EXACT(T32,'_key'!$A$395),FALSE),"✓","✗")) -> 0 | AD32: =IF(ISBLANK(V32),"",IF(IFERROR(ABS(V32-'_key'!$A$396)<=0.005,FALSE),"✓","✗")) -> 0
A33: ACC-0029 | X33: =IF(ISBLANK(H33),"",IF(IFERROR(ABS(H33-'_key'!$A$397)<=5e-05,FALSE),"✓","✗")) -> 0 | Y33: =IF(ISBLANK(K33),"",IF(IFERROR(ABS(K33-'_key'!$A$398)<=5e-05,FALSE),"✓","✗")) -> 0 | Z33: =IF(ISBLANK(L33),"",IF(IFERROR(ABS(L33-'_key'!$A$399)<=0.005,FALSE),"✓","✗")) -> 0 | AA33: =IF(ISBLANK(M33),"",IF(IFERROR(ABS(M33-'_key'!$A$400)<=0.005,FALSE),"✓","✗")) -> 0 | AB33: =IF(ISBLANK(S33),"",IF(IFERROR(ABS(S33-'_key'!$A$401)<=0.01,FALSE),"✓","✗")) -> 0 | AC33: =IF(ISBLANK(T33),"",IF(IFERROR(EXACT(T33,'_key'!$A$402),FALSE),"✓","✗")) -> 0 | AD33: =IF(ISBLANK(V33),"",IF(IFERROR(ABS(V33-'_key'!$A$403)<=0.005,FALSE),"✓","✗")) -> 0
A34: ACC-0030 | X34: =IF(ISBLANK(H34),"",IF(IFERROR(ABS(H34-'_key'!$A$404)<=5e-05,FALSE),"✓","✗")) -> 0 | Y34: =IF(ISBLANK(K34),"",IF(IFERROR(ABS(K34-'_key'!$A$405)<=5e-05,FALSE),"✓","✗")) -> 0 | Z34: =IF(ISBLANK(L34),"",IF(IFERROR(ABS(L34-'_key'!$A$406)<=0.005,FALSE),"✓","✗")) -> 0 | AA34: =IF(ISBLANK(M34),"",IF(IFERROR(ABS(M34-'_key'!$A$407)<=0.005,FALSE),"✓","✗")) -> 0 | AB34: =IF(ISBLANK(S34),"",IF(IFERROR(ABS(S34-'_key'!$A$408)<=0.01,FALSE),"✓","✗")) -> 0 | AC34: =IF(ISBLANK(T34),"",IF(IFERROR(EXACT(T34,'_key'!$A$409),FALSE),"✓","✗")) -> 0 | AD34: =IF(ISBLANK(V34),"",IF(IFERROR(ABS(V34-'_key'!$A$410)<=0.005,FALSE),"✓","✗")) -> 0
A35: ACC-0031 | X35: =IF(ISBLANK(H35),"",IF(IFERROR(ABS(H35-'_key'!$A$411)<=5e-05,FALSE),"✓","✗")) -> 0 | Y35: =IF(ISBLANK(K35),"",IF(IFERROR(ABS(K35-'_key'!$A$412)<=5e-05,FALSE),"✓","✗")) -> 0 | Z35: =IF(ISBLANK(L35),"",IF(IFERROR(ABS(L35-'_key'!$A$413)<=0.005,FALSE),"✓","✗")) -> 0 | AA35: =IF(ISBLANK(M35),"",IF(IFERROR(EXACT(M35,'_key'!$A$414),FALSE),"✓","✗")) -> 0 | AB35: =IF(ISBLANK(S35),"",IF(IFERROR(ABS(S35-'_key'!$A$415)<=0.01,FALSE),"✓","✗")) -> 0 | AC35: =IF(ISBLANK(T35),"",IF(IFERROR(EXACT(T35,'_key'!$A$416),FALSE),"✓","✗")) -> 0 | AD35: =IF(ISBLANK(V35),"",IF(IFERROR(ABS(V35-'_key'!$A$417)<=0.005,FALSE),"✓","✗")) -> 0
A36: ACC-0032 | X36: =IF(ISBLANK(H36),"",IF(IFERROR(ABS(H36-'_key'!$A$418)<=5e-05,FALSE),"✓","✗")) -> 0 | Y36: =IF(ISBLANK(K36),"",IF(IFERROR(ABS(K36-'_key'!$A$419)<=5e-05,FALSE),"✓","✗")) -> 0 | Z36: =IF(ISBLANK(L36),"",IF(IFERROR(ABS(L36-'_key'!$A$420)<=0.005,FALSE),"✓","✗")) -> 0 | AA36: =IF(ISBLANK(M36),"",IF(IFERROR(ABS(M36-'_key'!$A$421)<=0.005,FALSE),"✓","✗")) -> 0 | AB36: =IF(ISBLANK(S36),"",IF(IFERROR(ABS(S36-'_key'!$A$422)<=0.01,FALSE),"✓","✗")) -> 0 | AC36: =IF(ISBLANK(T36),"",IF(IFERROR(EXACT(T36,'_key'!$A$423),FALSE),"✓","✗")) -> 0 | AD36: =IF(ISBLANK(V36),"",IF(IFERROR(ABS(V36-'_key'!$A$424)<=0.005,FALSE),"✓","✗")) -> 0
A37: ACC-0033 | X37: =IF(ISBLANK(H37),"",IF(IFERROR(ABS(H37-'_key'!$A$425)<=5e-05,FALSE),"✓","✗")) -> 0 | Y37: =IF(ISBLANK(K37),"",IF(IFERROR(ABS(K37-'_key'!$A$426)<=5e-05,FALSE),"✓","✗")) -> 0 | Z37: =IF(ISBLANK(L37),"",IF(IFERROR(ABS(L37-'_key'!$A$427)<=0.005,FALSE),"✓","✗")) -> 0 | AA37: =IF(ISBLANK(M37),"",IF(IFERROR(EXACT(M37,'_key'!$A$428),FALSE),"✓","✗")) -> 0 | AB37: =IF(ISBLANK(S37),"",IF(IFERROR(ABS(S37-'_key'!$A$429)<=0.01,FALSE),"✓","✗")) -> 0 | AC37: =IF(ISBLANK(T37),"",IF(IFERROR(EXACT(T37,'_key'!$A$430),FALSE),"✓","✗")) -> 0 | AD37: =IF(ISBLANK(V37),"",IF(IFERROR(ABS(V37-'_key'!$A$431)<=0.005,FALSE),"✓","✗")) -> 0
A38: ACC-0034 | X38: =IF(ISBLANK(H38),"",IF(IFERROR(ABS(H38-'_key'!$A$432)<=5e-05,FALSE),"✓","✗")) -> 0 | Y38: =IF(ISBLANK(K38),"",IF(IFERROR(ABS(K38-'_key'!$A$433)<=5e-05,FALSE),"✓","✗")) -> 0 | Z38: =IF(ISBLANK(L38),"",IF(IFERROR(ABS(L38-'_key'!$A$434)<=0.005,FALSE),"✓","✗")) -> 0 | AA38: =IF(ISBLANK(M38),"",IF(IFERROR(ABS(M38-'_key'!$A$435)<=0.005,FALSE),"✓","✗")) -> 0 | AB38: =IF(ISBLANK(S38),"",IF(IFERROR(ABS(S38-'_key'!$A$436)<=0.01,FALSE),"✓","✗")) -> 0 | AC38: =IF(ISBLANK(T38),"",IF(IFERROR(EXACT(T38,'_key'!$A$437),FALSE),"✓","✗")) -> 0 | AD38: =IF(ISBLANK(V38),"",IF(IFERROR(ABS(V38-'_key'!$A$438)<=0.005,FALSE),"✓","✗")) -> 0
A39: ACC-0035 | X39: =IF(ISBLANK(H39),"",IF(IFERROR(ABS(H39-'_key'!$A$439)<=5e-05,FALSE),"✓","✗")) -> 0 | Y39: =IF(ISBLANK(K39),"",IF(IFERROR(ABS(K39-'_key'!$A$440)<=5e-05,FALSE),"✓","✗")) -> 0 | Z39: =IF(ISBLANK(L39),"",IF(IFERROR(ABS(L39-'_key'!$A$441)<=0.005,FALSE),"✓","✗")) -> 0 | AA39: =IF(ISBLANK(M39),"",IF(IFERROR(EXACT(M39,'_key'!$A$442),FALSE),"✓","✗")) -> 0 | AB39: =IF(ISBLANK(S39),"",IF(IFERROR(ABS(S39-'_key'!$A$443)<=0.01,FALSE),"✓","✗")) -> 0 | AC39: =IF(ISBLANK(T39),"",IF(IFERROR(EXACT(T39,'_key'!$A$444),FALSE),"✓","✗")) -> 0 | AD39: =IF(ISBLANK(V39),"",IF(IFERROR(ABS(V39-'_key'!$A$445)<=0.005,FALSE),"✓","✗")) -> 0
A40: ACC-0036 | X40: =IF(ISBLANK(H40),"",IF(IFERROR(ABS(H40-'_key'!$A$446)<=5e-05,FALSE),"✓","✗")) -> 0 | Y40: =IF(ISBLANK(K40),"",IF(IFERROR(ABS(K40-'_key'!$A$447)<=5e-05,FALSE),"✓","✗")) -> 0 | Z40: =IF(ISBLANK(L40),"",IF(IFERROR(ABS(L40-'_key'!$A$448)<=0.005,FALSE),"✓","✗")) -> 0 | AA40: =IF(ISBLANK(M40),"",IF(IFERROR(EXACT(M40,'_key'!$A$449),FALSE),"✓","✗")) -> 0 | AB40: =IF(ISBLANK(S40),"",IF(IFERROR(ABS(S40-'_key'!$A$450)<=0.01,FALSE),"✓","✗")) -> 0 | AC40: =IF(ISBLANK(T40),"",IF(IFERROR(EXACT(T40,'_key'!$A$451),FALSE),"✓","✗")) -> 0 | AD40: =IF(ISBLANK(V40),"",IF(IFERROR(ABS(V40-'_key'!$A$452)<=0.005,FALSE),"✓","✗")) -> 0
A41: ACC-0037 | X41: =IF(ISBLANK(H41),"",IF(IFERROR(ABS(H41-'_key'!$A$453)<=5e-05,FALSE),"✓","✗")) -> 0 | Y41: =IF(ISBLANK(K41),"",IF(IFERROR(ABS(K41-'_key'!$A$454)<=5e-05,FALSE),"✓","✗")) -> 0 | Z41: =IF(ISBLANK(L41),"",IF(IFERROR(ABS(L41-'_key'!$A$455)<=0.005,FALSE),"✓","✗")) -> 0 | AA41: =IF(ISBLANK(M41),"",IF(IFERROR(EXACT(M41,'_key'!$A$456),FALSE),"✓","✗")) -> 0 | AB41: =IF(ISBLANK(S41),"",IF(IFERROR(ABS(S41-'_key'!$A$457)<=0.01,FALSE),"✓","✗")) -> 0 | AC41: =IF(ISBLANK(T41),"",IF(IFERROR(EXACT(T41,'_key'!$A$458),FALSE),"✓","✗")) -> 0 | AD41: =IF(ISBLANK(V41),"",IF(IFERROR(ABS(V41-'_key'!$A$459)<=0.005,FALSE),"✓","✗")) -> 0
...

Sheet E4_Auditoria_Reportes
A1: E4 · Auditoría del uso de reportes
A2: Objetivo: con el log de uso (Report_Usage_Log) y el inventario (Report_Catalog) mide cuánto se usa realmente cada reporte, cuánto cuesta mantenerlo y genera una recomendación: Retirar, Consolidar, Automatizar o Mantener. Luego resume cuántas horas se liberarían.
A3: Contexto: la vacante pide 'analizar y auditar' los reportes actuales para saber qué mejorar, quitar o agregar. Fíjate en reportes duplicados (Login v1 vs v2, 'Copy of...'), reportes ad hoc que se piden tanto que conviene automatizarlos y reportes contractuales que nadie abre (¿se envían por otro lado?).
W4: Resumen para liderazgo
A5: ReportID | B5: ReportName | C5: Type | D5: Frequency | E5: Views (180d) | F5: Exports (180d) | G5: Usuarios únicos | H5: Último uso | I5: Días sin uso | J5: Views últimos 90d | K5: Horas mant./mes | L5: Costo por vista (USD) | M5: Recomendación | O5: ✓E | P5: ✓F | Q5: ✓G | R5: ✓H | S5: ✓J | T5: ✓L | U5: ✓M | W5: Recomendación | X5: # Reportes | Y5: Horas/mes | Z5: Chk
A6: Dado | B6: XLOOKUP | C6: XLOOKUP | D6: XLOOKUP | E6: COUNTIFS(tbl_ReportLog[ReportID], A7, ...[Action], "View") | F6: Igual con "Export" | G6: IFERROR(ROWS(UNIQUE(FILTER(tbl_ReportLog[UserEmail], tbl_ReportLog[ReportID]=A7))), 0) | H6: Si no hay registros → ""; si no MAXIFS(tbl_ReportLog[Date], ...) | I6: IF(H7="", "", AsOfDate − H7) | J6: COUNTIFS(..., "View", ...[Date], ">"&AsOfDate-90) | K6: XLOOKUP MaintHrsPerMonth | L6: IFERROR(K7*6*CostPerHour/E7, "") | M6: IFS: Contractual→"Mantener (contractual)"; J=0→"Retirar"; J<10→"Consolidar / revisar"; Ad hoc y J≥30→"Automatizar"; si no "Mantener" | X6: COUNTIF($M$7:$M$n, W7) | Y6: SUMIF(..., $K$7:$K$n)
A7: RPT-001 | O7: =IF(ISBLANK(E7),"",IF(IFERROR(ABS(E7-'_key'!$A$1198)<=0.005,FALSE),"✓","✗")) -> 0 | P7: =IF(ISBLANK(F7),"",IF(IFERROR(ABS(F7-'_key'!$A$1199)<=0.005,FALSE),"✓","✗")) -> 0 | Q7: =IF(ISBLANK(G7),"",IF(IFERROR(ABS(G7-'_key'!$A$1200)<=0.005,FALSE),"✓","✗")) -> 0 | R7: =IF(ISBLANK(H7),"",IF(IFERROR(ABS(H7-'_key'!$A$1201)<=0.005,FALSE),"✓","✗")) -> 0 | S7: =IF(ISBLANK(J7),"",IF(IFERROR(ABS(J7-'_key'!$A$1202)<=0.005,FALSE),"✓","✗")) -> 0 | T7: =IF(ISBLANK(L7),"",IF(IFERROR(ABS(L7-'_key'!$A$1203)<=0.01,FALSE),"✓","✗")) -> 0 | U7: =IF(ISBLANK(M7),"",IF(IFERROR(EXACT(M7,'_key'!$A$1204),FALSE),"✓","✗")) -> 0 | W7: Retirar | Z7: =IF(ISBLANK(X7),"",IF(IFERROR(ABS(X7-'_key'!$A$1450)<=0.005,FALSE),"✓","✗")) -> 0
A8: RPT-002 | O8: =IF(ISBLANK(E8),"",IF(IFERROR(ABS(E8-'_key'!$A$1205)<=0.005,FALSE),"✓","✗")) -> 0 | P8: =IF(ISBLANK(F8),"",IF(IFERROR(ABS(F8-'_key'!$A$1206)<=0.005,FALSE),"✓","✗")) -> 0 | Q8: =IF(ISBLANK(G8),"",IF(IFERROR(ABS(G8-'_key'!$A$1207)<=0.005,FALSE),"✓","✗")) -> 0 | R8: =IF(ISBLANK(H8),"",IF(IFERROR(ABS(H8-'_key'!$A$1208)<=0.005,FALSE),"✓","✗")) -> 0 | S8: =IF(ISBLANK(J8),"",IF(IFERROR(ABS(J8-'_key'!$A$1209)<=0.005,FALSE),"✓","✗")) -> 0 | T8: =IF(ISBLANK(L8),"",IF(IFERROR(ABS(L8-'_key'!$A$1210)<=0.01,FALSE),"✓","✗")) -> 0 | U8: =IF(ISBLANK(M8),"",IF(IFERROR(EXACT(M8,'_key'!$A$1211),FALSE),"✓","✗")) -> 0 | W8: Consolidar / revisar | Z8: =IF(ISBLANK(X8),"",IF(IFERROR(ABS(X8-'_key'!$A$1452)<=0.005,FALSE),"✓","✗")) -> 0
